Workbook

Sheet LEEME
A1: M18 · Swap-set 2×2 con intervalos binomiales — calculadora
A3: Qué es: la matriz 2×2 política vieja × política nueva (swap-set) con tasas de malos, IC exactos por celda,
A4: variación de mora de la cartera, su IC (diseño pareado), punto de quiebre del swap-in, cotas sin supuestos (Manski),
A5: test binomial de la cohorte swap-in contra su PD y un bloque de costo de exploración.
A7: Cómo usarla: edita SOLO las celdas amarillas. Valores por defecto = Banco Austral OOT, iso-aprobación 90,2%
A8: (ambas aprueban 51/1.680 · swap-out 30/128 · swap-in 12/128 · ambas rechazan 26/68; PD calibrada swap-in 5,1%).
A10: Hojas:
A11: Swap2x2 — matriz, IC Clopper-Pearson (BETA.INV) y Wilson, Δ de cartera, IC de Newcombe, quiebre, Manski.
A12: Binomial — pmf auxiliar (x = 0..600) para el p-valor bilateral «minlike» (el de scipy.stats.binomtest).
A13: Exploracion — banda de exploración: explorados útiles, error estándar, costo neto esperado.
A15: Supuestos y convenciones:
A16: · Target 1 = malo (90+ a 12 meses). Celdas disjuntas ⇒ binomiales independientes condicionales a la pertenencia.
... A22: · n máximo por celda para la hoja Binomial: 600.

Sheet Swap2x2
A1: Swap-set 2×2 (edita las celdas amarillas)
A3: Confianza | B3: 0.95
A4: α | B4: =1-B3
A5: z (1−α/2) | B5: =_xlfn.NORM.S.INV(1-B4/2)
A7: Celda | B7: n | C7: malos | D7: tasa malos | E7: CP inferior | F7: CP superior | G7: Wilson inf. | H7: Wilson sup. | I7: EAD medio (MM$) | J7: Pérdida realizada (MM$) | K7: LGD | L7: 0.45
A8: ambas aprueban | B8: 1680 | C8: 51 | D8: =C8/B8 | E8: =IF(C8=0,0,_xlfn.BETA.INV($B$4/2,C8,B8-C8+1)) | F8: =IF(C8=B8,1,_xlfn.BETA.INV(1-$B$4/2,C8+1,B8-C8)) | G8: =(D8+$B$5^2/(2*B8)-$B$5*SQRT(D8*(1-D8)/B8+$B$5^2/(4*B8^2)))/(1+$B$5^2/B8) | H8: =(D8+$B$5^2/(2*B8)+$B$5*SQRT(D8*(1-D8)/B8+$B$5^2/(4*B8^2)))/(1+$B$5^2/B8) | I8: 2.5 | J8: =$L$7*C8*I8
A9: swap-out (sale) | B9: 128 | C9: 30 | D9: =C9/B9 | E9: =IF(C9=0,0,_xlfn.BETA.INV($B$4/2,C9,B9-C9+1)) | F9: =IF(C9=B9,1,_xlfn.BETA.INV(1-$B$4/2,C9+1,B9-C9)) | G9: =(D9+$B$5^2/(2*B9)-$B$5*SQRT(D9*(1-D9)/B9+$B$5^2/(4*B9^2)))/(1+$B$5^2/B9) | H9: =(D9+$B$5^2/(2*B9)+$B$5*SQRT(D9*(1-D9)/B9+$B$5^2/(4*B9^2)))/(1+$B$5^2/B9) | I9: 2.5 | J9: =$L$7*C9*I9
A10: swap-in (entra) | B10: 128 | C10: 12 | D10: =C10/B10 | E10: =IF(C10=0,0,_xlfn.BETA.INV($B$4/2,C10,B10-C10+1)) | F10: =IF(C10=B10,1,_xlfn.BETA.INV(1-$B$4/2,C10+1,B10-C10)) | G10: =(D10+$B$5^2/(2*B10)-$B$5*SQRT(D10*(1-D10)/B10+$B$5^2/(4*B10^2)))/(1+$B$5^2/B10) | H10: =(D10+$B$5^2/(2*B10)+$B$5*SQRT(D10*(1-D10)/B10+$B$5^2/(4*B10^2)))/(1+$B$5^2/B10) | I10: 2.5 | J10: =$L$7*C10*I10
A11: ambas rechazan | B11: 68 | C11: 26 | D11: =C11/B11 | E11: =IF(C11=0,0,_xlfn.BETA.INV($B$4/2,C11,B11-C11+1)) | F11: =IF(C11=B11,1,_xlfn.BETA.INV(1-$B$4/2,C11+1,B11-C11)) | G11: =(D11+$B$5^2/(2*B11)-$B$5*SQRT(D11*(1-D11)/B11+$B$5^2/(4*B11^2)))/(1+$B$5^2/B11) | H11: =(D11+$B$5^2/(2*B11)+$B$5*SQRT(D11*(1-D11)/B11+$B$5^2/(4*B11^2)))/(1+$B$5^2/B11) | I11: 2.5 | J11: =$L$7*C11*I11
A13: Cartera aprobada
A14: K vieja (n11 + n10) | B14: =B8+B9
A15: K nueva (n11 + n01) | B15: =B8+B10
A16: ¿Iso-aprobación? (n01 = n10) | B16: =IF(B9=B10,"sí","NO")
A17: Mora vieja | B17: =(C8+C9)/B14
A18: Mora nueva | B18: =(C8+C10)/B15
A19: Δ = nueva − vieja | B19: =B18-B17
A20: Δ por identidad [n01(b01−BRv) − n10(b10−BRv)]/Kn | B20: =(B10*(D10-B17)-B9*(D9-B17))/B15
A21: Variación relativa | B21: =B18/B17-1
A23: Swap-in vs swap-out
A24: b_in − b_out | B24: =D10-D9
A25: Newcombe inferior (b_in − b_out) | B25: =B24-SQRT((D10-G10)^2+(H9-D9)^2)
A26: Newcombe superior (b_in − b_out) | B26: =B24+SQRT((H10-D10)^2+(D9-G9)^2)
A27: IC de Δ (iso: Newcombe × s/K) inferior | B27: =IF(B9=B10,B25*B10/B15,"no iso")
A28: IC de Δ (iso: Newcombe × s/K) superior | B28: =IF(B9=B10,B26*B10/B15,"no iso")
A29: EE de Δ por método delta (Wald, general) | B29: =SQRT(B8*D8*(1-D8)*(1/B15-1/B14)^2+B10*D10*(1-D10)/B15^2+B9*D9*(1-D9)/B14^2)
A30: IC Wald de Δ inferior | B30: =B19-B5*B29
A31: IC Wald de Δ superior | B31: =B19+B5*B29
A33: Robustez sin supuestos
A34: b_in de quiebre (mora nueva = vieja) | B34: =(B15*B17-C8)/B10
A35: Múltiplo de quiebre (b_in* / b_in) | B35: =IF(D10>0,B34/D10,"∞")
A36: Manski: mora nueva si b_in = 0 | B36: =C8/B15
A37: Manski: mora nueva si b_in = 1 | B37: =(C8+B10)/B15
A39: Pérdida en pesos (EAD medio por celda)
A40: Pérdida vieja (MM$) | B40: =J8+J9
A41: Pérdida nueva (MM$) | B41: =J8+J10
A42: Δ pérdida = swap-in − swap-out | B42: =J10-J9
A43: Monto vieja / nueva (MM$) | B43: =B8*I8+B9*I9 | C43: =B8*I8+B10*I10
A45: Cohorte swap-in vs su PD
A46: PD calibrada media del swap-in | B46: 0.051
A47: Malos esperados | B47: =B10*B46
...

Sheet Binomial
A1: x | B1: pmf(x; n, p0) | C1: ¿pmf ≤ pmf(k)? | D1: pmf(k) observado | E1: p minlike
A2: 0 | B2: =IF(A2<=Swap2x2!$B$10,_xlfn.BINOM.DIST(A2,Swap2x2!$B$10,Swap2x2!$B$46,FALSE),0) | C2: =IF(AND(A2<=Swap2x2!$B$10,B2<=$D$2*(1+1E-7)),1,0) | D2: =INDEX(B2:B602,Swap2x2!C10+1) | E2: =MIN(1,SUMPRODUCT(C2:C602,B2:B602))
A3: 1 | B3: =IF(A3<=Swap2x2!$B$10,_xlfn.BINOM.DIST(A3,Swap2x2!$B$10,Swap2x2!$B$46,FALSE),0) | C3: =IF(AND(A3<=Swap2x2!$B$10,B3<=$D$2*(1+1E-7)),1,0)
A4: 2 | B4: =IF(A4<=Swap2x2!$B$10,_xlfn.BINOM.DIST(A4,Swap2x2!$B$10,Swap2x2!$B$46,FALSE),0) | C4: =IF(AND(A4<=Swap2x2!$B$10,B4<=$D$2*(1+1E-7)),1,0)
A5: 3 | B5: =IF(A5<=Swap2x2!$B$10,_xlfn.BINOM.DIST(A5,Swap2x2!$B$10,Swap2x2!$B$46,FALSE),0) | C5: =IF(AND(A5<=Swap2x2!$B$10,B5<=$D$2*(1+1E-7)),1,0)
A6: 4 | B6: =IF(A6<=Swap2x2!$B$10,_xlfn.BINOM.DIST(A6,Swap2x2!$B$10,Swap2x2!$B$46,FALSE),0) | C6: =IF(AND(A6<=Swap2x2!$B$10,B6<=$D$2*(1+1E-7)),1,0)
A7: 5 | B7: =IF(A7<=Swap2x2!$B$10,_xlfn.BINOM.DIST(A7,Swap2x2!$B$10,Swap2x2!$B$46,FALSE),0) | C7: =IF(AND(A7<=Swap2x2!$B$10,B7<=$D$2*(1+1E-7)),1,0)
A8: 6 | B8: =IF(A8<=Swap2x2!$B$10,_xlfn.BINOM.DIST(A8,Swap2x2!$B$10,Swap2x2!$B$46,FALSE),0) | C8: =IF(AND(A8<=Swap2x2!$B$10,B8<=$D$2*(1+1E-7)),1,0)
A9: 7 | B9: =IF(A9<=Swap2x2!$B$10,_xlfn.BINOM.DIST(A9,Swap2x2!$B$10,Swap2x2!$B$46,FALSE),0) | C9: =IF(AND(A9<=Swap2x2!$B$10,B9<=$D$2*(1+1E-7)),1,0)
A10: 8 | B10: =IF(A10<=Swap2x2!$B$10,_xlfn.BINOM.DIST(A10,Swap2x2!$B$10,Swap2x2!$B$46,FALSE),0) | C10: =IF(AND(A10<=Swap2x2!$B$10,B10<=$D$2*(1+1E-7)),1,0)
A11: 9 | B11: =IF(A11<=Swap2x2!$B$10,_xlfn.BINOM.DIST(A11,Swap2x2!$B$10,Swap2x2!$B$46,FALSE),0) | C11: =IF(AND(A11<=Swap2x2!$B$10,B11<=$D$2*(1+1E-7)),1,0)
A12: 10 | B12: =IF(A12<=Swap2x2!$B$10,_xlfn.BINOM.DIST(A12,Swap2x2!$B$10,Swap2x2!$B$46,FALSE),0) | C12: =IF(AND(A12<=Swap2x2!$B$10,B12<=$D$2*(1+1E-7)),1,0)
A13: 11 | B13: =IF(A13<=Swap2x2!$B$10,_xlfn.BINOM.DIST(A13,Swap2x2!$B$10,Swap2x2!$B$46,FALSE),0) | C13: =IF(AND(A13<=Swap2x2!$B$10,B13<=$D$2*(1+1E-7)),1,0)
A14: 12 | B14: =IF(A14<=Swap2x2!$B$10,_xlfn.BINOM.DIST(A14,Swap2x2!$B$10,Swap2x2!$B$46,FALSE),0) | C14: =IF(AND(A14<=Swap2x2!$B$10,B14<=$D$2*(1+1E-7)),1,0)
... A602: 600 | B602: =IF(A602<=Swap2x2!$B$10,_xlfn.BINOM.DIST(A602,Swap2x2!$B$10,Swap2x2!$B$46,FALSE),0) | C602: =IF(AND(A602<=Swap2x2!$B$10,B602<=$D$2*(1+1E-7)),1,0)

Sheet Exploracion
A1: Banda de exploración: aprobar al azar una fracción ε de los rechazados
A3: Solicitudes por mes | B3: 3000
A4: Tasa de rechazo de la política vieja | B4: 0.075
A5: Fracción de rechazados en la región swap-in | B5: 0.7
A6: ε (fracción explorada) | B6: 0.1
A7: Meses de exploración | B7: 6
A8: Mora esperada del swap-in (supuesto previo) | B8: 0.23
A9: Mora esperada del resto de rechazados | B9: 0.55
A10: EAD medio (MM$) | B10: 2.5
A11: LGD | B11: 0.45
A12: Resultados | B12: 0.09
A13: Rechazados en el periodo | B13: =B3*B4*B7
A14: Explorados (todos los rechazados) | B14: =B13*B6
A15: Explorados útiles (en swap-in) | B15: =B14*B5
A16: Error estándar de la mora estimada del swap-in | B16: =SQRT(B8*(1-B8)/B15)
A17: Mora media de los explorados | B17: =B5*B8+(1-B5)*B9
A18: Costo neto esperado, todos (MM$) | B18: =B14*B10*(B11*B17-B12)
A19: Costo neto esperado, focalizada (MM$) | B19: =B15*B10*(B11*B8-B12)
A20: Costo por explorado útil, todos (MM$) | B20: =B18/B15
A21: Costo por explorado útil, focalizada (MM$) | B21: =B19/B15
A22: Mora de quiebre del swap-in (margen / LGD) | B22: =B12/B11
A23: Distancia al quiebre en EE (|b* − b| / EE) | B23: =ABS(B22-B8)/B16
A24: P(decisión errada) aprox. normal | B24: =_xlfn.NORM.S.DIST(-B23,TRUE)
