Workbook

Sheet LEEME
A1: M17 · Tabla de estrategia para crédito de motos (planilla principal de la Serie 2)
A2: Qué es
A3: Una calculadora viva de estrategia de originación para un crédito de moto con cuota fija y la moto como garantía. Para cada banda de la master scale calcula PD de vida, LGD por mes de default, pérdida esperada (EL), valor presente neto esperado (utilidad), tasa requerida y si cabe bajo la tasa máxima convencional (TMC). Luego arma la tabla de estrategia (un cutoff por fila) y el cutoff de breakeven.
A4: Todos los números por defecto son GENÉRICOS e ILUSTRATIVOS (rangos plausibles, no datos de ninguna empresa). Reemplácelos por los suyos: la planilla es una herramienta de razonamiento, no una fuente de datos.
A5: Cómo usarla
A6: 1. Hoja Parametros: edite las celdas AMARILLAS (precio, pie, tasa, plazo ≤ 60, depreciación, recupero, costos, TMC, escala del score, apetito). Las celdas GRISES son derivadas: no las edite.
A7: 2. Hoja Bandas: edite la PD a 12 meses calibrada de cada banda, la mezcla de solicitudes (% que debe sumar 100%) y el monto medio financiado por banda (por defecto, el monto del caso).
A8: 3. Lea Estrategia (una fila por cutoff: aprobación, PD media, monto, EL, margen, utilidad), Breakeven (odds y score de breakeven, sensibilidad) y LGD_motos (cronograma, valor de la moto y LGD por mes de default).
A9: 4. Default_bandas es la maquinaria: distribución de tiempos de default por banda bajo riesgos proporcionales. Normalmente no se toca.
A10: Mapa de hojas
A11: Parametros — supuestos del caso motos, costos, TMC, escala (PDO/ancla), apetito y parámetros del modelo simple del curso.
A12: Bandas — 8 bandas A1…E (master scale del curso: 20 puntos por banda); PD12, mezcla, monto; PD de vida, EL, E[VPN], tasa requerida y chequeo TMC.
... A33: Acompaña a: M17_estrategia_cutoff.md (derivaciones) y M17_estrategia_cutoff.py (notebook Marimo con verdad conocida).

Sheet Parametros
A1: Parámetros del caso motos y de la estrategia
A3: Parámetro | B3: Valor | C3: Unidad | D3: Rango plausible / nota
A4: Crédito y moto
A5: Precio de la moto | B5: 4000000 | C5: CLP | D5: 3–6 MM$ (ilustrativo)
A6: Pie | B6: 0.2 | C6: % precio | D6: 10–30%
A7: Monto financiado | B7: =B5*(1-B6) | C7: CLP | D7: precio·(1 − pie)
A8: Tasa de interés mensual (base) | B8: 0.022 | C8: % mensual | D8: 1,9–2,6% (ilustrativo); debe quedar bajo la TMC mensual
A9: Tasa lineal anual equivalente | B9: =B8*12 | C9: % anual | D9: forma en que la CMF expresa la TMC (lineal, base 360)
A10: Plazo | B10: 36 | C10: meses | D10: 24–48; MÁXIMO 60 (tamaño del cronograma)
A11: Depreciación anual de la moto | B11: 0.2 | C11: % anual | D11: 15–25% (geométrica). Referencia fiscal española: ≈84% del valor a 1 año, 67% a 2 (verificar)
A12: Castigo inicial (salida de tienda / precio de liquidación) | B12: 0.1 | C12: % precio | D12: 0–20%
A13: Costo de recupero y remate | B13: 0.15 | C13: % valor de venta | D13: 10–20% (retiro, bodegaje, martillero, legal)
A14: Meses desde el default hasta la venta | B14: 6 | C14: meses | D14: 4–8
A15: Probabilidad de recuperar físicamente la moto (π) | B15: 0.6 | C15: % | D15: 40–85%: el supuesto MÁS incierto; estímelo con sus casos de cobranza
A16: Mes de máxima intensidad de default | B16: 7 | C16: mes | D16: 5–10; debe ser > 3. Define la forma de la curva de default
A18: Costos y rentabilidad
A19: Costo de fondos (anual efectivo) | B19: 0.1 | C19: % anual | D19: 7–14% (ilustrativo para una fintech)
A20: Tasa de descuento mensual | B20: =(1+B19)^(1/12)-1 | C20: % mensual | D20: (1 + c_f)^(1/12) − 1
A21: Costo operativo | B21: 0.04 | C21: % anual del saldo | D21: 3–6% (servicing, cobranza temprana)
A22: Costo de adquisición por crédito | B22: 200000 | C22: CLP | D22: 100–300 mil (comisión dealer, originación, evaluación)
A23: Margen objetivo para pricing | B23: 0.05 | C23: % monto en VP | D23: E[VPN] exigido por crédito = margen · monto
A25: Tasa máxima convencional (TMC)
A26: TMC anual del tramo del crédito | B26: 0.345 | C26: % lineal anual | D26: 34,50%: tramo > 50 y ≤ 200 UF, certificado CMF vigente desde 14-08-2026. ACTUALIZAR mensualmente
A27: TMC mensual | B27: =B26/12 | C27: % mensual | D27: lineal anual / 12
A28: Valor de la UF | B28: 41000 | C28: CLP | D28: ≈ 41.000 a fines de septiembre de 2026; actualizar
A29: Monto financiado en UF | B29: =B7/B28 | C29: UF | D29: define el tramo de TMC
A30: Tramo de TMC que corresponde | B30: =IF(B29<=50,"≤ 50 UF",IF(B29<=200,"> 50 y ≤ 200 UF","> 200 UF")) | D30: si no es «> 50 y ≤ 200 UF», cambie la TMC de B26 (≤ 50 UF: 41,50%; > 200 y ≤ 5.000 UF: 30,75%, mismo certificado)
A31: ¿La tasa base cumple la TMC? | B31: =IF(B8<=B27,"sí","NO: tasa sobre el máximo legal")
A33: Escala del score (curso: PDO 20, 600 @ 50:1)
A34: PDO (puntos para duplicar las odds) | B34: 20 | C34: puntos | D34: convención del curso
A35: Score ancla | B35: 600 | C35: puntos
A36: Odds en el ancla (buenos:malos) | B36: 50 | C36: odds | D36: 600 = 50:1 = PD 1,96%
A37: Factor | B37: =B34/LN(2) | D37: PDO/ln 2 = 28,8539
A38: Offset | B38: =B35-B37*LN(B36) | D38: ancla − factor·ln(odds) = 487,1229
A40: Estrategia y apetito
A41: Solicitudes por mes | B41: 1000 | C41: solicitudes | D41: volumen ilustrativo
A42: Apetito: PD12 media máxima de la cartera aprobada | B42: 0.045 | C42: % | D42: lo fija el directorio; el curso usó 2,5% de mora para Austral
A43: Aprobación mínima exigida por comercial | B43: 0.45 | C43: % solicitudes | D43: ilustrativo; con 60% ningún cutoff cumple ambas condiciones (pruébelo)
A45: Modelo simple del curso (un período, EAD = monto, LGD fija) — hoja Breakeven, bloque A
A46: LGD fija | B46: 0.45 | C46: % | D46: curso: 45% (consumo sin garantía, convención)
...

Sheet Bandas
A1: Bandas de la master scale (curso: 20 puntos por banda) — economía por banda
A2: PD12 por defecto = PD calibrada media de Banco Austral por banda (clase 5); mezcla de solicitudes ilustrativa de motos (desplazada a bandas bajas). Edite las columnas amarillas.
A4: idx | B4: banda | C4: score mín | D4: score máx | E4: PD12 calibrada | F4: PD en punto medio (escala) | G4: % solicitudes | H4: monto medio financiado | I4: monto / M0 | J4: PD de vida | K4: EL por crédito (VP) | L4: EL / monto | M4: E[VPN] por crédito (tasa base) | N4: E[VPN] por crédito (a TMC) | O4: tasa mensual requerida | P4: ¿cabe bajo TMC? | Q4: decisión breakeven | R4: utilidad esperada del mes (MM$)
A5: 1 | B5: A1 | C5: =Parametros!$B$35+Parametros!$B$34*(3) | D5: abierta | E5: 0.0011 | F5: banda abierta | G5: 0.02 | H5: =Parametros!$B$7 | I5: =H5/Parametros!$B$7 | J5: =Default_bandas!D6 | K5: =I5*Default_bandas!D9 | L5: =K5/H5 | M5: =I5*((1-J5)*LGD_motos!$B$6+Default_bandas!D7+Parametros!$B$22)-Parametros!$B$22 | N5: =I5*((1-J5)*LGD_motos!$B$7+Default_bandas!D8+Parametros!$B$22)-Parametros!$B$22 | O5: =Parametros!$B$8+(Parametros!$B$23*H5-M5)*(Parametros!$B$27-Parametros!$B$8)/(N5-M5) | P5: =IF(O5<=Parametros!$B$27,"sí","no") | Q5: =IF(M5>0,"aprobar","rechazar") | R5: =Parametros!$B$41*G5*M5/1000000
A6: 2 | B6: A2 | C6: =Parametros!$B$35+Parametros!$B$34*(2) | D6: =Parametros!$B$35+Parametros!$B$34*(3) | E6: 0.0036 | F6: =1/(1+EXP(((C6+D6)/2-Parametros!$B$38)/Parametros!$B$37)) | G6: 0.03 | H6: =Parametros!$B$7 | I6: =H6/Parametros!$B$7 | J6: =Default_bandas!E6 | K6: =I6*Default_bandas!E9 | L6: =K6/H6 | M6: =I6*((1-J6)*LGD_motos!$B$6+Default_bandas!E7+Parametros!$B$22)-Parametros!$B$22 | N6: =I6*((1-J6)*LGD_motos!$B$7+Default_bandas!E8+Parametros!$B$22)-Parametros!$B$22 | O6: =Parametros!$B$8+(Parametros!$B$23*H6-M6)*(Parametros!$B$27-Parametros!$B$8)/(N6-M6) | P6: =IF(O6<=Parametros!$B$27,"sí","no") | Q6: =IF(M6>0,"aprobar","rechazar") | R6: =Parametros!$B$41*G6*M6/1000000
A7: 3 | B7: B1 | C7: =Parametros!$B$35+Parametros!$B$34*(1) | D7: =Parametros!$B$35+Parametros!$B$34*(2) | E7: 0.0072 | F7: =1/(1+EXP(((C7+D7)/2-Parametros!$B$38)/Parametros!$B$37)) | G7: 0.05 | H7: =Parametros!$B$7 | I7: =H7/Parametros!$B$7 | J7: =Default_bandas!F6 | K7: =I7*Default_bandas!F9 | L7: =K7/H7 | M7: =I7*((1-J7)*LGD_motos!$B$6+Default_bandas!F7+Parametros!$B$22)-Parametros!$B$22 | N7: =I7*((1-J7)*LGD_motos!$B$7+Default_bandas!F8+Parametros!$B$22)-Parametros!$B$22 | O7: =Parametros!$B$8+(Parametros!$B$23*H7-M7)*(Parametros!$B$27-Parametros!$B$8)/(N7-M7) | P7: =IF(O7<=Parametros!$B$27,"sí","no") | Q7: =IF(M7>0,"aprobar","rechazar") | R7: =Parametros!$B$41*G7*M7/1000000
A8: 4 | B8: B2 | C8: =Parametros!$B$35+Parametros!$B$34*(0) | D8: =Parametros!$B$35+Parametros!$B$34*(1) | E8: 0.0141 | F8: =1/(1+EXP(((C8+D8)/2-Parametros!$B$38)/Parametros!$B$37)) | G8: 0.08 | H8: =Parametros!$B$7 | I8: =H8/Parametros!$B$7 | J8: =Default_bandas!G6 | K8: =I8*Default_bandas!G9 | L8: =K8/H8 | M8: =I8*((1-J8)*LGD_motos!$B$6+Default_bandas!G7+Parametros!$B$22)-Parametros!$B$22 | N8: =I8*((1-J8)*LGD_motos!$B$7+Default_bandas!G8+Parametros!$B$22)-Parametros!$B$22 | O8: =Parametros!$B$8+(Parametros!$B$23*H8-M8)*(Parametros!$B$27-Parametros!$B$8)/(N8-M8) | P8: =IF(O8<=Parametros!$B$27,"sí","no") | Q8: =IF(M8>0,"aprobar","rechazar") | R8: =Parametros!$B$41*G8*M8/1000000
A9: 5 | B9: C1 | C9: =Parametros!$B$35+Parametros!$B$34*(-1) | D9: =Parametros!$B$35+Parametros!$B$34*(0) | E9: 0.0279 | F9: =1/(1+EXP(((C9+D9)/2-Parametros!$B$38)/Parametros!$B$37)) | G9: 0.12 | H9: =Parametros!$B$7 | I9: =H9/Parametros!$B$7 | J9: =Default_bandas!H6 | K9: =I9*Default_bandas!H9 | L9: =K9/H9 | M9: =I9*((1-J9)*LGD_motos!$B$6+Default_bandas!H7+Parametros!$B$22)-Parametros!$B$22 | N9: =I9*((1-J9)*LGD_motos!$B$7+Default_bandas!H8+Parametros!$B$22)-Parametros!$B$22 | O9: =Parametros!$B$8+(Parametros!$B$23*H9-M9)*(Parametros!$B$27-Parametros!$B$8)/(N9-M9) | P9: =IF(O9<=Parametros!$B$27,"sí","no") | Q9: =IF(M9>0,"aprobar","rechazar") | R9: =Parametros!$B$41*G9*M9/1000000
A10: 6 | B10: C2 | C10: =Parametros!$B$35+Parametros!$B$34*(-2) | D10: =Parametros!$B$35+Parametros!$B$34*(-1) | E10: 0.0543 | F10: =1/(1+EXP(((C10+D10)/2-Parametros!$B$38)/Parametros!$B$37)) | G10: 0.17 | H10: =Parametros!$B$7 | I10: =H10/Parametros!$B$7 | J10: =Default_bandas!I6 | K10: =I10*Default_bandas!I9 | L10: =K10/H10 | M10: =I10*((1-J10)*LGD_motos!$B$6+Default_bandas!I7+Parametros!$B$22)-Parametros!$B$22 | N10: =I10*((1-J10)*LGD_motos!$B$7+Default_bandas!I8+Parametros!$B$22)-Parametros!$B$22 | O10: =Parametros!$B$8+(Parametros!$B$23*H10-M10)*(Parametros!$B$27-Parametros!$B$8)/(N10-M10) | P10: =IF(O10<=Parametros!$B$27,"sí","no") | Q10: =IF(M10>0,"aprobar","rechazar") | R10: =Parametros!$B$41*G10*M10/1000000
A11: 7 | B11: D | C11: =Parametros!$B$35+Parametros!$B$34*(-3) | D11: =Parametros!$B$35+Parametros!$B$34*(-2) | E11: 0.1016 | F11: =1/(1+EXP(((C11+D11)/2-Parametros!$B$38)/Parametros!$B$37)) | G11: 0.2 | H11: =Parametros!$B$7 | I11: =H11/Parametros!$B$7 | J11: =Default_bandas!J6 | K11: =I11*Default_bandas!J9 | L11: =K11/H11 | M11: =I11*((1-J11)*LGD_motos!$B$6+Default_bandas!J7+Parametros!$B$22)-Parametros!$B$22 | N11: =I11*((1-J11)*LGD_motos!$B$7+Default_bandas!J8+Parametros!$B$22)-Parametros!$B$22 | O11: =Parametros!$B$8+(Parametros!$B$23*H11-M11)*(Parametros!$B$27-Parametros!$B$8)/(N11-M11) | P11: =IF(O11<=Parametros!$B$27,"sí","no") | Q11: =IF(M11>0,"aprobar","rechazar") | R11: =Parametros!$B$41*G11*M11/1000000
A12: 8 | B12: E | C12: abierta | D12: =Parametros!$B$35+Parametros!$B$34*(-3) | E12: 0.2675 | F12: banda abierta | G12: 0.33 | H12: =Parametros!$B$7 | I12: =H12/Parametros!$B$7 | J12: =Default_bandas!K6 | K12: =I12*Default_bandas!K9 | L12: =K12/H12 | M12: =I12*((1-J12)*LGD_motos!$B$6+Default_bandas!K7+Parametros!$B$22)-Parametros!$B$22 | N12: =I12*((1-J12)*LGD_motos!$B$7+Default_bandas!K8+Parametros!$B$22)-Parametros!$B$22 | O12: =Parametros!$B$8+(Parametros!$B$23*H12-M12)*(Parametros!$B$27-Parametros!$B$8)/(N12-M12) | P12: =IF(O12<=Parametros!$B$27,"sí","no") | Q12: =IF(M12>0,"aprobar","rechazar") | R12: =Parametros!$B$41*G12*M12/1000000
B13: Total | E13: =SUMPRODUCT(G5:G12,E5:E12)/SUM(G5:G12) | G13: =SUM(G5:G12) | J13: =SUMPRODUCT(G5:G12,J5:J12)/SUM(G5:G12) | R13: =SUM(R5:R12)
B15: Chequeo | C15: =IF(ABS(G13-1)<0.0001,"la mezcla suma 100%","ATENCIÓN: la mezcla no suma 100%")
B17: Lectura: E[VPN] > 0 ⇒ la banda paga su riesgo a la tasa base. «Tasa mensual requerida» = tasa que deja un E[VPN] igual al margen objetivo (secante entre tasa base y TMC; fuera de ese intervalo es extrapolación). Si no cabe bajo la TMC, no existe precio legal que pague el riesgo con ese margen: rechazar, pedir más pie o acortar plazo.

Sheet Estrategia
A1: Tabla de estrategia del caso motos: una fila por cutoff (fronteras de banda)
A2: Cada fila aprueba desde A1 hasta la banda indicada. Utilidad = E[VPN] al costo de fondos. Margen = Utilidad + EL (antes de pérdidas de crédito). Todo por mes, con las solicitudes de Parametros.
A4: aprueba hasta banda | B4: cutoff (score ≥) | C4: aprobación | D4: n aprobados | E4: PD12 media aprobada | F4: PD de vida media | G4: monto aprobado (MM$) | H4: EL (VP, MM$) | I4: margen (MM$) | J4: utilidad esperada (MM$) | K4: EL / monto | L4: E[VPN] del crédito marginal | M4: ¿cumple apetito PD? | N4: ¿cumple aprobación mín.? | O4: aux: aprobación si cumple ambas
A5: A1 | B5: =Bandas!C5 | C5: =SUMPRODUCT((Bandas!$A$5:$A$12<=1)*Bandas!$G$5:$G$12) | D5: =C5*Parametros!$B$41 | E5: =SUMPRODUCT((Bandas!$A$5:$A$12<=1)*Bandas!$G$5:$G$12*Bandas!$E$5:$E$12)/C5 | F5: =SUMPRODUCT((Bandas!$A$5:$A$12<=1)*Bandas!$G$5:$G$12*Bandas!$J$5:$J$12)/C5 | G5: =Parametros!$B$41*SUMPRODUCT((Bandas!$A$5:$A$12<=1)*Bandas!$G$5:$G$12*Bandas!$H$5:$H$12)/1000000 | H5: =Parametros!$B$41*SUMPRODUCT((Bandas!$A$5:$A$12<=1)*Bandas!$G$5:$G$12*Bandas!$K$5:$K$12)/1000000 | I5: =J5+H5 | J5: =Parametros!$B$41*SUMPRODUCT((Bandas!$A$5:$A$12<=1)*Bandas!$G$5:$G$12*Bandas!$M$5:$M$12)/1000000 | K5: =H5/G5 | L5: =Bandas!M5 | M5: =IF(E5<=Parametros!$B$42,"sí","no") | N5: =IF(C5>=Parametros!$B$43,"sí","no") | O5: =IF(AND(M5="sí",N5="sí"),C5,-1)
A6: A2 | B6: =Bandas!C6 | C6: =SUMPRODUCT((Bandas!$A$5:$A$12<=2)*Bandas!$G$5:$G$12) | D6: =C6*Parametros!$B$41 | E6: =SUMPRODUCT((Bandas!$A$5:$A$12<=2)*Bandas!$G$5:$G$12*Bandas!$E$5:$E$12)/C6 | F6: =SUMPRODUCT((Bandas!$A$5:$A$12<=2)*Bandas!$G$5:$G$12*Bandas!$J$5:$J$12)/C6 | G6: =Parametros!$B$41*SUMPRODUCT((Bandas!$A$5:$A$12<=2)*Bandas!$G$5:$G$12*Bandas!$H$5:$H$12)/1000000 | H6: =Parametros!$B$41*SUMPRODUCT((Bandas!$A$5:$A$12<=2)*Bandas!$G$5:$G$12*Bandas!$K$5:$K$12)/1000000 | I6: =J6+H6 | J6: =Parametros!$B$41*SUMPRODUCT((Bandas!$A$5:$A$12<=2)*Bandas!$G$5:$G$12*Bandas!$M$5:$M$12)/1000000 | K6: =H6/G6 | L6: =Bandas!M6 | M6: =IF(E6<=Parametros!$B$42,"sí","no") | N6: =IF(C6>=Parametros!$B$43,"sí","no") | O6: =IF(AND(M6="sí",N6="sí"),C6,-1)
A7: B1 | B7: =Bandas!C7 | C7: =SUMPRODUCT((Bandas!$A$5:$A$12<=3)*Bandas!$G$5:$G$12) | D7: =C7*Parametros!$B$41 | E7: =SUMPRODUCT((Bandas!$A$5:$A$12<=3)*Bandas!$G$5:$G$12*Bandas!$E$5:$E$12)/C7 | F7: =SUMPRODUCT((Bandas!$A$5:$A$12<=3)*Bandas!$G$5:$G$12*Bandas!$J$5:$J$12)/C7 | G7: =Parametros!$B$41*SUMPRODUCT((Bandas!$A$5:$A$12<=3)*Bandas!$G$5:$G$12*Bandas!$H$5:$H$12)/1000000 | H7: =Parametros!$B$41*SUMPRODUCT((Bandas!$A$5:$A$12<=3)*Bandas!$G$5:$G$12*Bandas!$K$5:$K$12)/1000000 | I7: =J7+H7 | J7: =Parametros!$B$41*SUMPRODUCT((Bandas!$A$5:$A$12<=3)*Bandas!$G$5:$G$12*Bandas!$M$5:$M$12)/1000000 | K7: =H7/G7 | L7: =Bandas!M7 | M7: =IF(E7<=Parametros!$B$42,"sí","no") | N7: =IF(C7>=Parametros!$B$43,"sí","no") | O7: =IF(AND(M7="sí",N7="sí"),C7,-1)
A8: B2 | B8: =Bandas!C8 | C8: =SUMPRODUCT((Bandas!$A$5:$A$12<=4)*Bandas!$G$5:$G$12) | D8: =C8*Parametros!$B$41 | E8: =SUMPRODUCT((Bandas!$A$5:$A$12<=4)*Bandas!$G$5:$G$12*Bandas!$E$5:$E$12)/C8 | F8: =SUMPRODUCT((Bandas!$A$5:$A$12<=4)*Bandas!$G$5:$G$12*Bandas!$J$5:$J$12)/C8 | G8: =Parametros!$B$41*SUMPRODUCT((Bandas!$A$5:$A$12<=4)*Bandas!$G$5:$G$12*Bandas!$H$5:$H$12)/1000000 | H8: =Parametros!$B$41*SUMPRODUCT((Bandas!$A$5:$A$12<=4)*Bandas!$G$5:$G$12*Bandas!$K$5:$K$12)/1000000 | I8: =J8+H8 | J8: =Parametros!$B$41*SUMPRODUCT((Bandas!$A$5:$A$12<=4)*Bandas!$G$5:$G$12*Bandas!$M$5:$M$12)/1000000 | K8: =H8/G8 | L8: =Bandas!M8 | M8: =IF(E8<=Parametros!$B$42,"sí","no") | N8: =IF(C8>=Parametros!$B$43,"sí","no") | O8: =IF(AND(M8="sí",N8="sí"),C8,-1)
A9: C1 | B9: =Bandas!C9 | C9: =SUMPRODUCT((Bandas!$A$5:$A$12<=5)*Bandas!$G$5:$G$12) | D9: =C9*Parametros!$B$41 | E9: =SUMPRODUCT((Bandas!$A$5:$A$12<=5)*Bandas!$G$5:$G$12*Bandas!$E$5:$E$12)/C9 | F9: =SUMPRODUCT((Bandas!$A$5:$A$12<=5)*Bandas!$G$5:$G$12*Bandas!$J$5:$J$12)/C9 | G9: =Parametros!$B$41*SUMPRODUCT((Bandas!$A$5:$A$12<=5)*Bandas!$G$5:$G$12*Bandas!$H$5:$H$12)/1000000 | H9: =Parametros!$B$41*SUMPRODUCT((Bandas!$A$5:$A$12<=5)*Bandas!$G$5:$G$12*Bandas!$K$5:$K$12)/1000000 | I9: =J9+H9 | J9: =Parametros!$B$41*SUMPRODUCT((Bandas!$A$5:$A$12<=5)*Bandas!$G$5:$G$12*Bandas!$M$5:$M$12)/1000000 | K9: =H9/G9 | L9: =Bandas!M9 | M9: =IF(E9<=Parametros!$B$42,"sí","no") | N9: =IF(C9>=Parametros!$B$43,"sí","no") | O9: =IF(AND(M9="sí",N9="sí"),C9,-1)
A10: C2 | B10: =Bandas!C10 | C10: =SUMPRODUCT((Bandas!$A$5:$A$12<=6)*Bandas!$G$5:$G$12) | D10: =C10*Parametros!$B$41 | E10: =SUMPRODUCT((Bandas!$A$5:$A$12<=6)*Bandas!$G$5:$G$12*Bandas!$E$5:$E$12)/C10 | F10: =SUMPRODUCT((Bandas!$A$5:$A$12<=6)*Bandas!$G$5:$G$12*Bandas!$J$5:$J$12)/C10 | G10: =Parametros!$B$41*SUMPRODUCT((Bandas!$A$5:$A$12<=6)*Bandas!$G$5:$G$12*Bandas!$H$5:$H$12)/1000000 | H10: =Parametros!$B$41*SUMPRODUCT((Bandas!$A$5:$A$12<=6)*Bandas!$G$5:$G$12*Bandas!$K$5:$K$12)/1000000 | I10: =J10+H10 | J10: =Parametros!$B$41*SUMPRODUCT((Bandas!$A$5:$A$12<=6)*Bandas!$G$5:$G$12*Bandas!$M$5:$M$12)/1000000 | K10: =H10/G10 | L10: =Bandas!M10 | M10: =IF(E10<=Parametros!$B$42,"sí","no") | N10: =IF(C10>=Parametros!$B$43,"sí","no") | O10: =IF(AND(M10="sí",N10="sí"),C10,-1)
A11: D | B11: =Bandas!C11 | C11: =SUMPRODUCT((Bandas!$A$5:$A$12<=7)*Bandas!$G$5:$G$12) | D11: =C11*Parametros!$B$41 | E11: =SUMPRODUCT((Bandas!$A$5:$A$12<=7)*Bandas!$G$5:$G$12*Bandas!$E$5:$E$12)/C11 | F11: =SUMPRODUCT((Bandas!$A$5:$A$12<=7)*Bandas!$G$5:$G$12*Bandas!$J$5:$J$12)/C11 | G11: =Parametros!$B$41*SUMPRODUCT((Bandas!$A$5:$A$12<=7)*Bandas!$G$5:$G$12*Bandas!$H$5:$H$12)/1000000 | H11: =Parametros!$B$41*SUMPRODUCT((Bandas!$A$5:$A$12<=7)*Bandas!$G$5:$G$12*Bandas!$K$5:$K$12)/1000000 | I11: =J11+H11 | J11: =Parametros!$B$41*SUMPRODUCT((Bandas!$A$5:$A$12<=7)*Bandas!$G$5:$G$12*Bandas!$M$5:$M$12)/1000000 | K11: =H11/G11 | L11: =Bandas!M11 | M11: =IF(E11<=Parametros!$B$42,"sí","no") | N11: =IF(C11>=Parametros!$B$43,"sí","no") | O11: =IF(AND(M11="sí",N11="sí"),C11,-1)
A12: E | B12: sin corte | C12: =SUMPRODUCT((Bandas!$A$5:$A$12<=8)*Bandas!$G$5:$G$12) | D12: =C12*Parametros!$B$41 | E12: =SUMPRODUCT((Bandas!$A$5:$A$12<=8)*Bandas!$G$5:$G$12*Bandas!$E$5:$E$12)/C12 | F12: =SUMPRODUCT((Bandas!$A$5:$A$12<=8)*Bandas!$G$5:$G$12*Bandas!$J$5:$J$12)/C12 | G12: =Parametros!$B$41*SUMPRODUCT((Bandas!$A$5:$A$12<=8)*Bandas!$G$5:$G$12*Bandas!$H$5:$H$12)/1000000 | H12: =Parametros!$B$41*SUMPRODUCT((Bandas!$A$5:$A$12<=8)*Bandas!$G$5:$G$12*Bandas!$K$5:$K$12)/1000000 | I12: =J12+H12 | J12: =Parametros!$B$41*SUMPRODUCT((Bandas!$A$5:$A$12<=8)*Bandas!$G$5:$G$12*Bandas!$M$5:$M$12)/1000000 | K12: =H12/G12 | L12: =Bandas!M12 | M12: =IF(E12<=Parametros!$B$42,"sí","no") | N12: =IF(C12>=Parametros!$B$43,"sí","no") | O12: =IF(AND(M12="sí",N12="sí"),C12,-1)
A14: Resumen
A15: Cutoff de máxima utilidad (aprueba hasta la banda) | G15: =INDEX(A5:A12,MATCH(MAX(J5:J12),J5:J12,0))
A16: Utilidad máxima (MM$ por mes) | G16: =MAX(J5:J12)
A17: Aprobación en el cutoff de máxima utilidad | G17: =INDEX(C5:C12,MATCH(MAX(J5:J12),J5:J12,0))
A18: Cutoff por apetito (el más laxo que cumple PD máx. y aprobación mín.) | G18: =IF(MAX(O5:O12)<0,"ninguno cumple",INDEX(A5:A12,MATCH(MAX(O5:O12),O5:O12,0)))
A19: Utilidad en el cutoff por apetito (MM$) | G19: =IF(MAX(O5:O12)<0,0,INDEX(J5:J12,MATCH(MAX(O5:O12),O5:O12,0)))
A20: Precio sombra del apetito (utilidad sacrificada, MM$) | G20: =IF(MAX(O5:O12)<0,0,G16-G19)
A22: Lectura: el cutoff de máxima utilidad aprueba toda banda con E[VPN] > 0 (condición marginal). El apetito es una restricción sobre el PROMEDIO de la cartera: si es más estricto, la diferencia de utilidad es su precio sombra. Con el cutoff en fronteras de banda, el óptimo continuo (hoja Breakeven) puede caer DENTRO de una banda.

Sheet Breakeven
A1: Odds y score de breakeven
A3: A. Modelo del curso: un período, EAD = monto, LGD fija
A4: k = costo de fondos + costos (% monto) | B4: =Parametros!$B$48+Parametros!$B$49
A5: g = ganancia si bueno = r − k | B5: =Parametros!$B$47-B4
A6: l = pérdida si malo = LGD + k | B6: =Parametros!$B$46+B4
A7: Odds de breakeven = l / g | B7: =IF(B5<=0,"sin breakeven (r ≤ k)",B6/B5)
A8: PD de breakeven = g / (g + l) | B8: =IF(B5<=0,"—",B5/(B5+B6))
A9: Score de breakeven = offset + factor·ln(l/g) | B9: =IF(B5<=0,"—",Parametros!$B$38+Parametros!$B$37*LN(B7))
A10: Banda donde cae el corte | B10: =IF(B5<=0,"—",IF(B9>=Bandas!$C$5,"A1",IF(B9>=Bandas!$C$6,"A2",IF(B9>=Bandas!$C$7,"B1",IF(B9>=Bandas!$C$8,"B2",IF(B9>=Bandas!$C$9,"C1",IF(B9>=Bandas!$C$10,"C2",IF(B9>=Bandas!$C$11,"D","E"))))))))
A11: Duplicar l/g sube el corte en (puntos) = factor·ln 2 = PDO | B11: =Parametros!$B$37*LN(2)
A13: Mini-calculadora de pricing (modelo A): tasa mínima para aprobar una PD dada
A14: PD del cliente (editable) | B14: 0.08
A15: Tasa mínima r = (k + PD·LGD)/(1 − PD) | B15: =(B4+B14*Parametros!$B$46)/(1-B14)
A17: B. Caso motos: vida del crédito (tiempos de default comunes, límite PD → 0)
A18: G = VPN si bueno (LGD_motos) | B18: =LGD_motos!B6
A19: L = −E[VPN | malo] (LGD_motos) | B19: =-LGD_motos!B11
A20: Odds de breakeven de VIDA = L / G | B20: =IF(B18<=0,"sin breakeven (G ≤ 0)",B19/B18)
A21: PD de vida de breakeven = G/(G + L) | B21: =IF(B18<=0,"—",B18/(B18+B19))
A22: κ (LGD_motos) | B22: =LGD_motos!B10
A23: PD12 de breakeven = 1 − (1 − PDvida)^(1/κ) | B23: =IF(B18<=0,"—",1-(1-B21)^(1/B22))
A24: Score de breakeven (motos) | B24: =IF(B18<=0,"—",Parametros!$B$38+Parametros!$B$37*LN((1-B23)/B23))
A25: Banda donde cae el corte | B25: =IF(B18<=0,"—",IF(B24>=Bandas!$C$5,"A1",IF(B24>=Bandas!$C$6,"A2",IF(B24>=Bandas!$C$7,"B1",IF(B24>=Bandas!$C$8,"B2",IF(B24>=Bandas!$C$9,"C1",IF(B24>=Bandas!$C$10,"C2",IF(B24>=Bandas!$C$11,"D","E"))))))))
A26: Nota: el breakeven exacto (tiempos propios de cada banda, notebook M17 §7.2) es algo más ESTRICTO que este, porque en bandas riesgosas los malos caen antes y el default temprano es el más caro. Con los supuestos por defecto la diferencia es < 1 punto.
A29: C. Sensibilidad viva del modelo A (tornado): score de breakeven con un supuesto en su extremo
A30: supuesto | B30: valor bajo | C30: valor alto | D30: score (bajo) | E30: score (alto) | F30: rango (pts)
A31: LGD | B31: 0.35 | C31: 0.55 | D31: =Parametros!$B$38+Parametros!$B$37*LN((B31+Parametros!$B$48+Parametros!$B$49)/(Parametros!$B$47-Parametros!$B$48-Parametros!$B$49)) | E31: =Parametros!$B$38+Parametros!$B$37*LN((C31+Parametros!$B$48+Parametros!$B$49)/(Parametros!$B$47-Parametros!$B$48-Parametros!$B$49)) | F31: =ABS(E31-D31)
A32: Tasa anual r | B32: 0.21 | C32: 0.27 | D32: =Parametros!$B$38+Parametros!$B$37*LN((Parametros!$B$46+Parametros!$B$48+Parametros!$B$49)/(B32-Parametros!$B$48-Parametros!$B$49)) | E32: =Parametros!$B$38+Parametros!$B$37*LN((Parametros!$B$46+Parametros!$B$48+Parametros!$B$49)/(C32-Parametros!$B$48-Parametros!$B$49)) | F32: =ABS(E32-D32)
A33: Costo de fondos | B33: 0.04 | C33: 0.08 | D33: =Parametros!$B$38+Parametros!$B$37*LN((Parametros!$B$46+B33+Parametros!$B$49)/(Parametros!$B$47-B33-Parametros!$B$49)) | E33: =Parametros!$B$38+Parametros!$B$37*LN((Parametros!$B$46+C33+Parametros!$B$49)/(Parametros!$B$47-C33-Parametros!$B$49)) | F33: =ABS(E33-D33)
A34: Costos operativos + adquisición | B34: 0.04 | C34: 0.08 | D34: =Parametros!$B$38+Parametros!$B$37*LN((Parametros!$B$46+Parametros!$B$48+B34)/(Parametros!$B$47-Parametros!$B$48-B34)) | E34: =Parametros!$B$38+Parametros!$B$37*LN((Parametros!$B$46+Parametros!$B$48+C34)/(Parametros!$B$47-Parametros!$B$48-C34)) | F34: =ABS(E34-D34)
A35: TC: Δδ en log-odds (mueve el corte factor·Δδ) | B35: -0.25 | C35: 0.25 | D35: =$B$9+Parametros!$B$37*B35 | E35: =$B$9+Parametros!$B$37*C35 | F35: =ABS(E35-D35)
A37: Lectura: la fila TC no cambia la economía; dice cuánto debería moverse el corte en el score del modelo si la tendencia central verdadera difiere Δδ log-odds de la calibrada (±0,25 ⇒ ±7,2 pts). El tornado del caso motos completo (con depreciación, recupero, plazo, etc.) está en el notebook M17 §8.

Sheet LGD_motos
A1: Cronograma, valor de la moto y LGD por mes de default
A2: Default = 90+ DPD alcanzado en el mes d (4 ≤ d ≤ N+3); última cuota pagada: d−4. Columnas H–L repiten el cronograma a la TMC (para la tasa requerida por banda).
A3: Monto financiado M0 | B3: =Parametros!$B$7
A4: Cuota (tasa base) | B4: =Parametros!$B$7*Parametros!$B$8/(1-(1+Parametros!$B$8)^(-Parametros!$B$10))
A5: Cuota (a la TMC) | B5: =Parametros!$B$7*Parametros!$B$27/(1-(1+Parametros!$B$27)^(-Parametros!$B$10))
A6: VPN si BUENO, G (tasa base) | B6: =-Parametros!$B$7-Parametros!$B$22+INDEX($G$18:$G$81,Parametros!$B$10+1)
A7: VPN si BUENO (a la TMC) | B7: =-Parametros!$B$7-Parametros!$B$22+INDEX($L$18:$L$81,Parametros!$B$10+1)
A8: S12 = Σ forma, d ≤ 12 | B8: =SUMIF($A$18:$A$81,"<=12",$W$18:$W$81)
A9: SN = Σ forma, d ≤ N+3 | B9: =SUM($W$18:$W$81)
A10: κ = SN/S12 (PD vida = 1 − (1 − PD12)^κ) | B10: =B9/B8
A11: E[VPN | malo], tiempos comunes (tasa base) | B11: =SUMPRODUCT($Y$18:$Y$81,$T$18:$T$81)
A12: LGD ponderada (tiempos comunes × EAD) | B12: =SUMPRODUCT($Y$18:$Y$81,$S$18:$S$81,$N$18:$N$81)/SUMPRODUCT($Y$18:$Y$81,$N$18:$N$81)
A13: LGD si el default es en d = 4 (temprano) | B13: =INDEX($S$18:$S$81,5)
A14: LGD si el default es en d = N+3 (tardío) | B14: =INDEX($S$18:$S$81,Parametros!$B$10+4)
A15: Primer mes en que la moto neta cubre el saldo | B15: =IF(MAX($AA$18:$AA$81)=0,"nunca",INDEX($A$18:$A$81,MATCH(1,$AA$18:$AA$81,0)))
A17: mes k / d | B17: vigente | C17: cuota | D17: saldo B_k | E17: costo op. del mes | F17: flujo neto | G17: VP acumulado | H17: cuota TMC | I17: saldo TMC | J17: costo op. TMC | K17: flujo neto TMC | L17: VP acum. TMC | M17: ¿d válido? | N17: EAD(d) | O17: valor moto a la venta | P17: acreencia | Q17: recupero neto (si hay moto) | R17: LGD si se recupera | S17: LGD(d) esperada | T17: VPN si default en d | U17: EAD(d) TMC | V17: VPN si default en d (TMC) | W17: forma s(d) | X17: S(d) acumulada | Y17: peso w(d) = s/SN | Z17: EL | default en d (VP otorg.) | AA17: ¿moto neta ≥ saldo?
A18: 0 | B18: =IF(A18<=Parametros!$B$10,1,0) | C18: =IF(AND(A18>=1,A18<=Parametros!$B$10),$B$4,0) | D18: =IF(A18<=Parametros!$B$10,Parametros!$B$7*((1+Parametros!$B$8)^Parametros!$B$10-(1+Parametros!$B$8)^A18)/((1+Parametros!$B$8)^Parametros!$B$10-1),0) | E18: =0 | F18: =C18-E18 | G18: =F18/(1+Parametros!$B$20)^A18 | H18: =IF(AND(A18>=1,A18<=Parametros!$B$10),$B$5,0) | I18: =IF(A18<=Parametros!$B$10,Parametros!$B$7*((1+Parametros!$B$27)^Parametros!$B$10-(1+Parametros!$B$27)^A18)/((1+Parametros!$B$27)^Parametros!$B$10-1),0) | J18: =0 | K18: =H18-J18 | L18: =K18/(1+Parametros!$B$20)^A18 | M18: =IF(AND(A18>=4,A18<=Parametros!$B$10+3),1,0) | N18: =IF(M18=1,INDEX($D$18:$D$81,A18-3),0) | O18: =IF(M18=1,Parametros!$B$5*(1-Parametros!$B$12)*(1-Parametros!$B$11)^((A18+Parametros!$B$14)/12),0) | P18: =N18*(1+Parametros!$B$8)^(3+Parametros!$B$14) | Q18: =MIN(O18*(1-Parametros!$B$13),P18) | R18: =IF(M18=1,MAX(0,1-Q18/(1+Parametros!$B$20)^Parametros!$B$14/N18),0) | S18: =IF(M18=1,Parametros!$B$15*R18+(1-Parametros!$B$15),0) | T18: =IF(M18=1,-Parametros!$B$7-Parametros!$B$22+INDEX($G$18:$G$81,A18-3)+Parametros!$B$15*Q18/(1+Parametros!$B$20)^(A18+Parametros!$B$14),0) | U18: =IF(M18=1,INDEX($I$18:$I$81,A18-3),0) | V18: =IF(M18=1,-Parametros!$B$7-Parametros!$B$22+INDEX($L$18:$L$81,A18-3)+Parametros!$B$15*MIN(O18*(1-Parametros!$B$13),U18*(1+Parametros!$B$27)^(3+Parametros!$B$14))/(1+Parametros!$B$20)^(A18+Parametros!$B$14),0) | W18: =IF(M18=1,((A18-3)/(Parametros!$B$16-3))*EXP(1-(A18-3)/(Parametros!$B$16-3)),0) | X18: =W18 | Y18: =W18/$B$9 | Z18: =S18*N18/(1+Parametros!$B$20)^A18 | AA18: =IF(AND(M18=1,O18*(1-Parametros!$B$13)>=N18),1,0)
A19: 1 | B19: =IF(A19<=Parametros!$B$10,1,0) | C19: =IF(AND(A19>=1,A19<=Parametros!$B$10),$B$4,0) | D19: =IF(A19<=Parametros!$B$10,Parametros!$B$7*((1+Parametros!$B$8)^Parametros!$B$10-(1+Parametros!$B$8)^A19)/((1+Parametros!$B$8)^Parametros!$B$10-1),0) | E19: =IF(AND(A19>=1,A19<=Parametros!$B$10),Parametros!$B$21/12*D18,0) | F19: =C19-E19 | G19: =F19/(1+Parametros!$B$20)^A19+G18 | H19: =IF(AND(A19>=1,A19<=Parametros!$B$10),$B$5,0) | I19: =IF(A19<=Parametros!$B$10,Parametros!$B$7*((1+Parametros!$B$27)^Parametros!$B$10-(1+Parametros!$B$27)^A19)/((1+Parametros!$B$27)^Parametros!$B$10-1),0) | J19: =IF(AND(A19>=1,A19<=Parametros!$B$10),Parametros!$B$21/12*I18,0) | K19: =H19-J19 | L19: =K19/(1+Parametros!$B$20)^A19+L18 | M19: =IF(AND(A19>=4,A19<=Parametros!$B$10+3),1,0) | N19: =IF(M19=1,INDEX($D$18:$D$81,A19-3),0) | O19: =IF(M19=1,Parametros!$B$5*(1-Parametros!$B$12)*(1-Parametros!$B$11)^((A19+Parametros!$B$14)/12),0) | P19: =N19*(1+Parametros!$B$8)^(3+Parametros!$B$14) | Q19: =MIN(O19*(1-Parametros!$B$13),P19) | R19: =IF(M19=1,MAX(0,1-Q19/(1+Parametros!$B$20)^Parametros!$B$14/N19),0) | S19: =IF(M19=1,Parametros!$B$15*R19+(1-Parametros!$B$15),0) | T19: =IF(M19=1,-Parametros!$B$7-Parametros!$B$22+INDEX($G$18:$G$81,A19-3)+Parametros!$B$15*Q19/(1+Parametros!$B$20)^(A19+Parametros!$B$14),0) | U19: =IF(M19=1,INDEX($I$18:$I$81,A19-3),0) | V19: =IF(M19=1,-Parametros!$B$7-Parametros!$B$22+INDEX($L$18:$L$81,A19-3)+Parametros!$B$15*MIN(O19*(1-Parametros!$B$13),U19*(1+Parametros!$B$27)^(3+Parametros!$B$14))/(1+Parametros!$B$20)^(A19+Parametros!$B$14),0) | W19: =IF(M19=1,((A19-3)/(Parametros!$B$16-3))*EXP(1-(A19-3)/(Parametros!$B$16-3)),0) | X19: =W19+X18 | Y19: =W19/$B$9 | Z19: =S19*N19/(1+Parametros!$B$20)^A19 | AA19: =IF(AND(M19=1,O19*(1-Parametros!$B$13)>=N19),1,0)
A20: 2 | B20: =IF(A20<=Parametros!$B$10,1,0) | C20: =IF(AND(A20>=1,A20<=Parametros!$B$10),$B$4,0) | D20: =IF(A20<=Parametros!$B$10,Parametros!$B$7*((1+Parametros!$B$8)^Parametros!$B$10-(1+Parametros!$B$8)^A20)/((1+Parametros!$B$8)^Parametros!$B$10-1),0) | E20: =IF(AND(A20>=1,A20<=Parametros!$B$10),Parametros!$B$21/12*D19,0) | F20: =C20-E20 | G20: =F20/(1+Parametros!$B$20)^A20+G19 | H20: =IF(AND(A20>=1,A20<=Parametros!$B$10),$B$5,0) | I20: =IF(A20<=Parametros!$B$10,Parametros!$B$7*((1+Parametros!$B$27)^Parametros!$B$10-(1+Parametros!$B$27)^A20)/((1+Parametros!$B$27)^Parametros!$B$10-1),0) | J20: =IF(AND(A20>=1,A20<=Parametros!$B$10),Parametros!$B$21/12*I19,0) | K20: =H20-J20 | L20: =K20/(1+Parametros!$B$20)^A20+L19 | M20: =IF(AND(A20>=4,A20<=Parametros!$B$10+3),1,0) | N20: =IF(M20=1,INDEX($D$18:$D$81,A20-3),0) | O20: =IF(M20=1,Parametros!$B$5*(1-Parametros!$B$12)*(1-Parametros!$B$11)^((A20+Parametros!$B$14)/12),0) | P20: =N20*(1+Parametros!$B$8)^(3+Parametros!$B$14) | Q20: =MIN(O20*(1-Parametros!$B$13),P20) | R20: =IF(M20=1,MAX(0,1-Q20/(1+Parametros!$B$20)^Parametros!$B$14/N20),0) | S20: =IF(M20=1,Parametros!$B$15*R20+(1-Parametros!$B$15),0) | T20: =IF(M20=1,-Parametros!$B$7-Parametros!$B$22+INDEX($G$18:$G$81,A20-3)+Parametros!$B$15*Q20/(1+Parametros!$B$20)^(A20+Parametros!$B$14),0) | U20: =IF(M20=1,INDEX($I$18:$I$81,A20-3),0) | V20: =IF(M20=1,-Parametros!$B$7-Parametros!$B$22+INDEX($L$18:$L$81,A20-3)+Parametros!$B$15*MIN(O20*(1-Parametros!$B$13),U20*(1+Parametros!$B$27)^(3+Parametros!$B$14))/(1+Parametros!$B$20)^(A20+Parametros!$B$14),0) | W20: =IF(M20=1,((A20-3)/(Parametros!$B$16-3))*EXP(1-(A20-3)/(Parametros!$B$16-3)),0) | X20: =W20+X19 | Y20: =W20/$B$9 | Z20: =S20*N20/(1+Parametros!$B$20)^A20 | AA20: =IF(AND(M20=1,O20*(1-Parametros!$B$13)>=N20),1,0)
A21: 3 | B21: =IF(A21<=Parametros!$B$10,1,0) | C21: =IF(AND(A21>=1,A21<=Parametros!$B$10),$B$4,0) | D21: =IF(A21<=Parametros!$B$10,Parametros!$B$7*((1+Parametros!$B$8)^Parametros!$B$10-(1+Parametros!$B$8)^A21)/((1+Parametros!$B$8)^Parametros!$B$10-1),0) | E21: =IF(AND(A21>=1,A21<=Parametros!$B$10),Parametros!$B$21/12*D20,0) | F21: =C21-E21 | G21: =F21/(1+Parametros!$B$20)^A21+G20 | H21: =IF(AND(A21>=1,A21<=Parametros!$B$10),$B$5,0) | I21: =IF(A21<=Parametros!$B$10,Parametros!$B$7*((1+Parametros!$B$27)^Parametros!$B$10-(1+Parametros!$B$27)^A21)/((1+Parametros!$B$27)^Parametros!$B$10-1),0) | J21: =IF(AND(A21>=1,A21<=Parametros!$B$10),Parametros!$B$21/12*I20,0) | K21: =H21-J21 | L21: =K21/(1+Parametros!$B$20)^A21+L20 | M21: =IF(AND(A21>=4,A21<=Parametros!$B$10+3),1,0) | N21: =IF(M21=1,INDEX($D$18:$D$81,A21-3),0) | O21: =IF(M21=1,Parametros!$B$5*(1-Parametros!$B$12)*(1-Parametros!$B$11)^((A21+Parametros!$B$14)/12),0) | P21: =N21*(1+Parametros!$B$8)^(3+Parametros!$B$14) | Q21: =MIN(O21*(1-Parametros!$B$13),P21) | R21: =IF(M21=1,MAX(0,1-Q21/(1+Parametros!$B$20)^Parametros!$B$14/N21),0) | S21: =IF(M21=1,Parametros!$B$15*R21+(1-Parametros!$B$15),0) | T21: =IF(M21=1,-Parametros!$B$7-Parametros!$B$22+INDEX($G$18:$G$81,A21-3)+Parametros!$B$15*Q21/(1+Parametros!$B$20)^(A21+Parametros!$B$14),0) | U21: =IF(M21=1,INDEX($I$18:$I$81,A21-3),0) | V21: =IF(M21=1,-Parametros!$B$7-Parametros!$B$22+INDEX($L$18:$L$81,A21-3)+Parametros!$B$15*MIN(O21*(1-Parametros!$B$13),U21*(1+Parametros!$B$27)^(3+Parametros!$B$14))/(1+Parametros!$B$20)^(A21+Parametros!$B$14),0) | W21: =IF(M21=1,((A21-3)/(Parametros!$B$16-3))*EXP(1-(A21-3)/(Parametros!$B$16-3)),0) | X21: =W21+X20 | Y21: =W21/$B$9 | Z21: =S21*N21/(1+Parametros!$B$20)^A21 | AA21: =IF(AND(M21=1,O21*(1-Parametros!$B$13)>=N21),1,0)
A22: 4 | B22: =IF(A22<=Parametros!$B$10,1,0) | C22: =IF(AND(A22>=1,A22<=Parametros!$B$10),$B$4,0) | D22: =IF(A22<=Parametros!$B$10,Parametros!$B$7*((1+Parametros!$B$8)^Parametros!$B$10-(1+Parametros!$B$8)^A22)/((1+Parametros!$B$8)^Parametros!$B$10-1),0) | E22: =IF(AND(A22>=1,A22<=Parametros!$B$10),Parametros!$B$21/12*D21,0) | F22: =C22-E22 | G22: =F22/(1+Parametros!$B$20)^A22+G21 | H22: =IF(AND(A22>=1,A22<=Parametros!$B$10),$B$5,0) | I22: =IF(A22<=Parametros!$B$10,Parametros!$B$7*((1+Parametros!$B$27)^Parametros!$B$10-(1+Parametros!$B$27)^A22)/((1+Parametros!$B$27)^Parametros!$B$10-1),0) | J22: =IF(AND(A22>=1,A22<=Parametros!$B$10),Parametros!$B$21/12*I21,0) | K22: =H22-J22 | L22: =K22/(1+Parametros!$B$20)^A22+L21 | M22: =IF(AND(A22>=4,A22<=Parametros!$B$10+3),1,0) | N22: =IF(M22=1,INDEX($D$18:$D$81,A22-3),0) | O22: =IF(M22=1,Parametros!$B$5*(1-Parametros!$B$12)*(1-Parametros!$B$11)^((A22+Parametros!$B$14)/12),0) | P22: =N22*(1+Parametros!$B$8)^(3+Parametros!$B$14) | Q22: =MIN(O22*(1-Parametros!$B$13),P22) | R22: =IF(M22=1,MAX(0,1-Q22/(1+Parametros!$B$20)^Parametros!$B$14/N22),0) | S22: =IF(M22=1,Parametros!$B$15*R22+(1-Parametros!$B$15),0) | T22: =IF(M22=1,-Parametros!$B$7-Parametros!$B$22+INDEX($G$18:$G$81,A22-3)+Parametros!$B$15*Q22/(1+Parametros!$B$20)^(A22+Parametros!$B$14),0) | U22: =IF(M22=1,INDEX($I$18:$I$81,A22-3),0) | V22: =IF(M22=1,-Parametros!$B$7-Parametros!$B$22+INDEX($L$18:$L$81,A22-3)+Parametros!$B$15*MIN(O22*(1-Parametros!$B$13),U22*(1+Parametros!$B$27)^(3+Parametros!$B$14))/(1+Parametros!$B$20)^(A22+Parametros!$B$14),0) | W22: =IF(M22=1,((A22-3)/(Parametros!$B$16-3))*EXP(1-(A22-3)/(Parametros!$B$16-3)),0) | X22: =W22+X21 | Y22: =W22/$B$9 | Z22: =S22*N22/(1+Parametros!$B$20)^A22 | AA22: =IF(AND(M22=1,O22*(1-Parametros!$B$13)>=N22),1,0)
A23: 5 | B23: =IF(A23<=Parametros!$B$10,1,0) | C23: =IF(AND(A23>=1,A23<=Parametros!$B$10),$B$4,0) | D23: =IF(A23<=Parametros!$B$10,Parametros!$B$7*((1+Parametros!$B$8)^Parametros!$B$10-(1+Parametros!$B$8)^A23)/((1+Parametros!$B$8)^Parametros!$B$10-1),0) | E23: =IF(AND(A23>=1,A23<=Parametros!$B$10),Parametros!$B$21/12*D22,0) | F23: =C23-E23 | G23: =F23/(1+Parametros!$B$20)^A23+G22 | H23: =IF(AND(A23>=1,A23<=Parametros!$B$10),$B$5,0) | I23: =IF(A23<=Parametros!$B$10,Parametros!$B$7*((1+Parametros!$B$27)^Parametros!$B$10-(1+Parametros!$B$27)^A23)/((1+Parametros!$B$27)^Parametros!$B$10-1),0) | J23: =IF(AND(A23>=1,A23<=Parametros!$B$10),Parametros!$B$21/12*I22,0) | K23: =H23-J23 | L23: =K23/(1+Parametros!$B$20)^A23+L22 | M23: =IF(AND(A23>=4,A23<=Parametros!$B$10+3),1,0) | N23: =IF(M23=1,INDEX($D$18:$D$81,A23-3),0) | O23: =IF(M23=1,Parametros!$B$5*(1-Parametros!$B$12)*(1-Parametros!$B$11)^((A23+Parametros!$B$14)/12),0) | P23: =N23*(1+Parametros!$B$8)^(3+Parametros!$B$14) | Q23: =MIN(O23*(1-Parametros!$B$13),P23) | R23: =IF(M23=1,MAX(0,1-Q23/(1+Parametros!$B$20)^Parametros!$B$14/N23),0) | S23: =IF(M23=1,Parametros!$B$15*R23+(1-Parametros!$B$15),0) | T23: =IF(M23=1,-Parametros!$B$7-Parametros!$B$22+INDEX($G$18:$G$81,A23-3)+Parametros!$B$15*Q23/(1+Parametros!$B$20)^(A23+Parametros!$B$14),0) | U23: =IF(M23=1,INDEX($I$18:$I$81,A23-3),0) | V23: =IF(M23=1,-Parametros!$B$7-Parametros!$B$22+INDEX($L$18:$L$81,A23-3)+Parametros!$B$15*MIN(O23*(1-Parametros!$B$13),U23*(1+Parametros!$B$27)^(3+Parametros!$B$14))/(1+Parametros!$B$20)^(A23+Parametros!$B$14),0) | W23: =IF(M23=1,((A23-3)/(Parametros!$B$16-3))*EXP(1-(A23-3)/(Parametros!$B$16-3)),0) | X23: =W23+X22 | Y23: =W23/$B$9 | Z23: =S23*N23/(1+Parametros!$B$20)^A23 | AA23: =IF(AND(M23=1,O23*(1-Parametros!$B$13)>=N23),1,0)
A24: 6 | B24: =IF(A24<=Parametros!$B$10,1,0) | C24: =IF(AND(A24>=1,A24<=Parametros!$B$10),$B$4,0) | D24: =IF(A24<=Parametros!$B$10,Parametros!$B$7*((1+Parametros!$B$8)^Parametros!$B$10-(1+Parametros!$B$8)^A24)/((1+Parametros!$B$8)^Parametros!$B$10-1),0) | E24: =IF(AND(A24>=1,A24<=Parametros!$B$10),Parametros!$B$21/12*D23,0) | F24: =C24-E24 | G24: =F24/(1+Parametros!$B$20)^A24+G23 | H24: =IF(AND(A24>=1,A24<=Parametros!$B$10),$B$5,0) | I24: =IF(A24<=Parametros!$B$10,Parametros!$B$7*((1+Parametros!$B$27)^Parametros!$B$10-(1+Parametros!$B$27)^A24)/((1+Parametros!$B$27)^Parametros!$B$10-1),0) | J24: =IF(AND(A24>=1,A24<=Parametros!$B$10),Parametros!$B$21/12*I23,0) | K24: =H24-J24 | L24: =K24/(1+Parametros!$B$20)^A24+L23 | M24: =IF(AND(A24>=4,A24<=Parametros!$B$10+3),1,0) | N24: =IF(M24=1,INDEX($D$18:$D$81,A24-3),0) | O24: =IF(M24=1,Parametros!$B$5*(1-Parametros!$B$12)*(1-Parametros!$B$11)^((A24+Parametros!$B$14)/12),0) | P24: =N24*(1+Parametros!$B$8)^(3+Parametros!$B$14) | Q24: =MIN(O24*(1-Parametros!$B$13),P24) | R24: =IF(M24=1,MAX(0,1-Q24/(1+Parametros!$B$20)^Parametros!$B$14/N24),0) | S24: =IF(M24=1,Parametros!$B$15*R24+(1-Parametros!$B$15),0) | T24: =IF(M24=1,-Parametros!$B$7-Parametros!$B$22+INDEX($G$18:$G$81,A24-3)+Parametros!$B$15*Q24/(1+Parametros!$B$20)^(A24+Parametros!$B$14),0) | U24: =IF(M24=1,INDEX($I$18:$I$81,A24-3),0) | V24: =IF(M24=1,-Parametros!$B$7-Parametros!$B$22+INDEX($L$18:$L$81,A24-3)+Parametros!$B$15*MIN(O24*(1-Parametros!$B$13),U24*(1+Parametros!$B$27)^(3+Parametros!$B$14))/(1+Parametros!$B$20)^(A24+Parametros!$B$14),0) | W24: =IF(M24=1,((A24-3)/(Parametros!$B$16-3))*EXP(1-(A24-3)/(Parametros!$B$16-3)),0) | X24: =W24+X23 | Y24: =W24/$B$9 | Z24: =S24*N24/(1+Parametros!$B$20)^A24 | AA24: =IF(AND(M24=1,O24*(1-Parametros!$B$13)>=N24),1,0)
A25: 7 | B25: =IF(A25<=Parametros!$B$10,1,0) | C25: =IF(AND(A25>=1,A25<=Parametros!$B$10),$B$4,0) | D25: =IF(A25<=Parametros!$B$10,Parametros!$B$7*((1+Parametros!$B$8)^Parametros!$B$10-(1+Parametros!$B$8)^A25)/((1+Parametros!$B$8)^Parametros!$B$10-1),0) | E25: =IF(AND(A25>=1,A25<=Parametros!$B$10),Parametros!$B$21/12*D24,0) | F25: =C25-E25 | G25: =F25/(1+Parametros!$B$20)^A25+G24 | H25: =IF(AND(A25>=1,A25<=Parametros!$B$10),$B$5,0) | I25: =IF(A25<=Parametros!$B$10,Parametros!$B$7*((1+Parametros!$B$27)^Parametros!$B$10-(1+Parametros!$B$27)^A25)/((1+Parametros!$B$27)^Parametros!$B$10-1),0) | J25: =IF(AND(A25>=1,A25<=Parametros!$B$10),Parametros!$B$21/12*I24,0) | K25: =H25-J25 | L25: =K25/(1+Parametros!$B$20)^A25+L24 | M25: =IF(AND(A25>=4,A25<=Parametros!$B$10+3),1,0) | N25: =IF(M25=1,INDEX($D$18:$D$81,A25-3),0) | O25: =IF(M25=1,Parametros!$B$5*(1-Parametros!$B$12)*(1-Parametros!$B$11)^((A25+Parametros!$B$14)/12),0) | P25: =N25*(1+Parametros!$B$8)^(3+Parametros!$B$14) | Q25: =MIN(O25*(1-Parametros!$B$13),P25) | R25: =IF(M25=1,MAX(0,1-Q25/(1+Parametros!$B$20)^Parametros!$B$14/N25),0) | S25: =IF(M25=1,Parametros!$B$15*R25+(1-Parametros!$B$15),0) | T25: =IF(M25=1,-Parametros!$B$7-Parametros!$B$22+INDEX($G$18:$G$81,A25-3)+Parametros!$B$15*Q25/(1+Parametros!$B$20)^(A25+Parametros!$B$14),0) | U25: =IF(M25=1,INDEX($I$18:$I$81,A25-3),0) | V25: =IF(M25=1,-Parametros!$B$7-Parametros!$B$22+INDEX($L$18:$L$81,A25-3)+Parametros!$B$15*MIN(O25*(1-Parametros!$B$13),U25*(1+Parametros!$B$27)^(3+Parametros!$B$14))/(1+Parametros!$B$20)^(A25+Parametros!$B$14),0) | W25: =IF(M25=1,((A25-3)/(Parametros!$B$16-3))*EXP(1-(A25-3)/(Parametros!$B$16-3)),0) | X25: =W25+X24 | Y25: =W25/$B$9 | Z25: =S25*N25/(1+Parametros!$B$20)^A25 | AA25: =IF(AND(M25=1,O25*(1-Parametros!$B$13)>=N25),1,0)
A26: 8 | B26: =IF(A26<=Parametros!$B$10,1,0) | C26: =IF(AND(A26>=1,A26<=Parametros!$B$10),$B$4,0) | D26: =IF(A26<=Parametros!$B$10,Parametros!$B$7*((1+Parametros!$B$8)^Parametros!$B$10-(1+Parametros!$B$8)^A26)/((1+Parametros!$B$8)^Parametros!$B$10-1),0) | E26: =IF(AND(A26>=1,A26<=Parametros!$B$10),Parametros!$B$21/12*D25,0) | F26: =C26-E26 | G26: =F26/(1+Parametros!$B$20)^A26+G25 | H26: =IF(AND(A26>=1,A26<=Parametros!$B$10),$B$5,0) | I26: =IF(A26<=Parametros!$B$10,Parametros!$B$7*((1+Parametros!$B$27)^Parametros!$B$10-(1+Parametros!$B$27)^A26)/((1+Parametros!$B$27)^Parametros!$B$10-1),0) | J26: =IF(AND(A26>=1,A26<=Parametros!$B$10),Parametros!$B$21/12*I25,0) | K26: =H26-J26 | L26: =K26/(1+Parametros!$B$20)^A26+L25 | M26: =IF(AND(A26>=4,A26<=Parametros!$B$10+3),1,0) | N26: =IF(M26=1,INDEX($D$18:$D$81,A26-3),0) | O26: =IF(M26=1,Parametros!$B$5*(1-Parametros!$B$12)*(1-Parametros!$B$11)^((A26+Parametros!$B$14)/12),0) | P26: =N26*(1+Parametros!$B$8)^(3+Parametros!$B$14) | Q26: =MIN(O26*(1-Parametros!$B$13),P26) | R26: =IF(M26=1,MAX(0,1-Q26/(1+Parametros!$B$20)^Parametros!$B$14/N26),0) | S26: =IF(M26=1,Parametros!$B$15*R26+(1-Parametros!$B$15),0) | T26: =IF(M26=1,-Parametros!$B$7-Parametros!$B$22+INDEX($G$18:$G$81,A26-3)+Parametros!$B$15*Q26/(1+Parametros!$B$20)^(A26+Parametros!$B$14),0) | U26: =IF(M26=1,INDEX($I$18:$I$81,A26-3),0) | V26: =IF(M26=1,-Parametros!$B$7-Parametros!$B$22+INDEX($L$18:$L$81,A26-3)+Parametros!$B$15*MIN(O26*(1-Parametros!$B$13),U26*(1+Parametros!$B$27)^(3+Parametros!$B$14))/(1+Parametros!$B$20)^(A26+Parametros!$B$14),0) | W26: =IF(M26=1,((A26-3)/(Parametros!$B$16-3))*EXP(1-(A26-3)/(Parametros!$B$16-3)),0) | X26: =W26+X25 | Y26: =W26/$B$9 | Z26: =S26*N26/(1+Parametros!$B$20)^A26 | AA26: =IF(AND(M26=1,O26*(1-Parametros!$B$13)>=N26),1,0)
A27: 9 | B27: =IF(A27<=Parametros!$B$10,1,0) | C27: =IF(AND(A27>=1,A27<=Parametros!$B$10),$B$4,0) | D27: =IF(A27<=Parametros!$B$10,Parametros!$B$7*((1+Parametros!$B$8)^Parametros!$B$10-(1+Parametros!$B$8)^A27)/((1+Parametros!$B$8)^Parametros!$B$10-1),0) | E27: =IF(AND(A27>=1,A27<=Parametros!$B$10),Parametros!$B$21/12*D26,0) | F27: =C27-E27 | G27: =F27/(1+Parametros!$B$20)^A27+G26 | H27: =IF(AND(A27>=1,A27<=Parametros!$B$10),$B$5,0) | I27: =IF(A27<=Parametros!$B$10,Parametros!$B$7*((1+Parametros!$B$27)^Parametros!$B$10-(1+Parametros!$B$27)^A27)/((1+Parametros!$B$27)^Parametros!$B$10-1),0) | J27: =IF(AND(A27>=1,A27<=Parametros!$B$10),Parametros!$B$21/12*I26,0) | K27: =H27-J27 | L27: =K27/(1+Parametros!$B$20)^A27+L26 | M27: =IF(AND(A27>=4,A27<=Parametros!$B$10+3),1,0) | N27: =IF(M27=1,INDEX($D$18:$D$81,A27-3),0) | O27: =IF(M27=1,Parametros!$B$5*(1-Parametros!$B$12)*(1-Parametros!$B$11)^((A27+Parametros!$B$14)/12),0) | P27: =N27*(1+Parametros!$B$8)^(3+Parametros!$B$14) | Q27: =MIN(O27*(1-Parametros!$B$13),P27) | R27: =IF(M27=1,MAX(0,1-Q27/(1+Parametros!$B$20)^Parametros!$B$14/N27),0) | S27: =IF(M27=1,Parametros!$B$15*R27+(1-Parametros!$B$15),0) | T27: =IF(M27=1,-Parametros!$B$7-Parametros!$B$22+INDEX($G$18:$G$81,A27-3)+Parametros!$B$15*Q27/(1+Parametros!$B$20)^(A27+Parametros!$B$14),0) | U27: =IF(M27=1,INDEX($I$18:$I$81,A27-3),0) | V27: =IF(M27=1,-Parametros!$B$7-Parametros!$B$22+INDEX($L$18:$L$81,A27-3)+Parametros!$B$15*MIN(O27*(1-Parametros!$B$13),U27*(1+Parametros!$B$27)^(3+Parametros!$B$14))/(1+Parametros!$B$20)^(A27+Parametros!$B$14),0) | W27: =IF(M27=1,((A27-3)/(Parametros!$B$16-3))*EXP(1-(A27-3)/(Parametros!$B$16-3)),0) | X27: =W27+X26 | Y27: =W27/$B$9 | Z27: =S27*N27/(1+Parametros!$B$20)^A27 | AA27: =IF(AND(M27=1,O27*(1-Parametros!$B$13)>=N27),1,0)
A28: 10 | B28: =IF(A28<=Parametros!$B$10,1,0) | C28: =IF(AND(A28>=1,A28<=Parametros!$B$10),$B$4,0) | D28: =IF(A28<=Parametros!$B$10,Parametros!$B$7*((1+Parametros!$B$8)^Parametros!$B$10-(1+Parametros!$B$8)^A28)/((1+Parametros!$B$8)^Parametros!$B$10-1),0) | E28: =IF(AND(A28>=1,A28<=Parametros!$B$10),Parametros!$B$21/12*D27,0) | F28: =C28-E28 | G28: =F28/(1+Parametros!$B$20)^A28+G27 | H28: =IF(AND(A28>=1,A28<=Parametros!$B$10),$B$5,0) | I28: =IF(A28<=Parametros!$B$10,Parametros!$B$7*((1+Parametros!$B$27)^Parametros!$B$10-(1+Parametros!$B$27)^A28)/((1+Parametros!$B$27)^Parametros!$B$10-1),0) | J28: =IF(AND(A28>=1,A28<=Parametros!$B$10),Parametros!$B$21/12*I27,0) | K28: =H28-J28 | L28: =K28/(1+Parametros!$B$20)^A28+L27 | M28: =IF(AND(A28>=4,A28<=Parametros!$B$10+3),1,0) | N28: =IF(M28=1,INDEX($D$18:$D$81,A28-3),0) | O28: =IF(M28=1,Parametros!$B$5*(1-Parametros!$B$12)*(1-Parametros!$B$11)^((A28+Parametros!$B$14)/12),0) | P28: =N28*(1+Parametros!$B$8)^(3+Parametros!$B$14) | Q28: =MIN(O28*(1-Parametros!$B$13),P28) | R28: =IF(M28=1,MAX(0,1-Q28/(1+Parametros!$B$20)^Parametros!$B$14/N28),0) | S28: =IF(M28=1,Parametros!$B$15*R28+(1-Parametros!$B$15),0) | T28: =IF(M28=1,-Parametros!$B$7-Parametros!$B$22+INDEX($G$18:$G$81,A28-3)+Parametros!$B$15*Q28/(1+Parametros!$B$20)^(A28+Parametros!$B$14),0) | U28: =IF(M28=1,INDEX($I$18:$I$81,A28-3),0) | V28: =IF(M28=1,-Parametros!$B$7-Parametros!$B$22+INDEX($L$18:$L$81,A28-3)+Parametros!$B$15*MIN(O28*(1-Parametros!$B$13),U28*(1+Parametros!$B$27)^(3+Parametros!$B$14))/(1+Parametros!$B$20)^(A28+Parametros!$B$14),0) | W28: =IF(M28=1,((A28-3)/(Parametros!$B$16-3))*EXP(1-(A28-3)/(Parametros!$B$16-3)),0) | X28: =W28+X27 | Y28: =W28/$B$9 | Z28: =S28*N28/(1+Parametros!$B$20)^A28 | AA28: =IF(AND(M28=1,O28*(1-Parametros!$B$13)>=N28),1,0)
A29: 11 | B29: =IF(A29<=Parametros!$B$10,1,0) | C29: =IF(AND(A29>=1,A29<=Parametros!$B$10),$B$4,0) | D29: =IF(A29<=Parametros!$B$10,Parametros!$B$7*((1+Parametros!$B$8)^Parametros!$B$10-(1+Parametros!$B$8)^A29)/((1+Parametros!$B$8)^Parametros!$B$10-1),0) | E29: =IF(AND(A29>=1,A29<=Parametros!$B$10),Parametros!$B$21/12*D28,0) | F29: =C29-E29 | G29: =F29/(1+Parametros!$B$20)^A29+G28 | H29: =IF(AND(A29>=1,A29<=Parametros!$B$10),$B$5,0) | I29: =IF(A29<=Parametros!$B$10,Parametros!$B$7*((1+Parametros!$B$27)^Parametros!$B$10-(1+Parametros!$B$27)^A29)/((1+Parametros!$B$27)^Parametros!$B$10-1),0) | J29: =IF(AND(A29>=1,A29<=Parametros!$B$10),Parametros!$B$21/12*I28,0) | K29: =H29-J29 | L29: =K29/(1+Parametros!$B$20)^A29+L28 | M29: =IF(AND(A29>=4,A29<=Parametros!$B$10+3),1,0) | N29: =IF(M29=1,INDEX($D$18:$D$81,A29-3),0) | O29: =IF(M29=1,Parametros!$B$5*(1-Parametros!$B$12)*(1-Parametros!$B$11)^((A29+Parametros!$B$14)/12),0) | P29: =N29*(1+Parametros!$B$8)^(3+Parametros!$B$14) | Q29: =MIN(O29*(1-Parametros!$B$13),P29) | R29: =IF(M29=1,MAX(0,1-Q29/(1+Parametros!$B$20)^Parametros!$B$14/N29),0) | S29: =IF(M29=1,Parametros!$B$15*R29+(1-Parametros!$B$15),0) | T29: =IF(M29=1,-Parametros!$B$7-Parametros!$B$22+INDEX($G$18:$G$81,A29-3)+Parametros!$B$15*Q29/(1+Parametros!$B$20)^(A29+Parametros!$B$14),0) | U29: =IF(M29=1,INDEX($I$18:$I$81,A29-3),0) | V29: =IF(M29=1,-Parametros!$B$7-Parametros!$B$22+INDEX($L$18:$L$81,A29-3)+Parametros!$B$15*MIN(O29*(1-Parametros!$B$13),U29*(1+Parametros!$B$27)^(3+Parametros!$B$14))/(1+Parametros!$B$20)^(A29+Parametros!$B$14),0) | W29: =IF(M29=1,((A29-3)/(Parametros!$B$16-3))*EXP(1-(A29-3)/(Parametros!$B$16-3)),0) | X29: =W29+X28 | Y29: =W29/$B$9 | Z29: =S29*N29/(1+Parametros!$B$20)^A29 | AA29: =IF(AND(M29=1,O29*(1-Parametros!$B$13)>=N29),1,0)
A30: 12 | B30: =IF(A30<=Parametros!$B$10,1,0) | C30: =IF(AND(A30>=1,A30<=Parametros!$B$10),$B$4,0) | D30: =IF(A30<=Parametros!$B$10,Parametros!$B$7*((1+Parametros!$B$8)^Parametros!$B$10-(1+Parametros!$B$8)^A30)/((1+Parametros!$B$8)^Parametros!$B$10-1),0) | E30: =IF(AND(A30>=1,A30<=Parametros!$B$10),Parametros!$B$21/12*D29,0) | F30: =C30-E30 | G30: =F30/(1+Parametros!$B$20)^A30+G29 | H30: =IF(AND(A30>=1,A30<=Parametros!$B$10),$B$5,0) | I30: =IF(A30<=Parametros!$B$10,Parametros!$B$7*((1+Parametros!$B$27)^Parametros!$B$10-(1+Parametros!$B$27)^A30)/((1+Parametros!$B$27)^Parametros!$B$10-1),0) | J30: =IF(AND(A30>=1,A30<=Parametros!$B$10),Parametros!$B$21/12*I29,0) | K30: =H30-J30 | L30: =K30/(1+Parametros!$B$20)^A30+L29 | M30: =IF(AND(A30>=4,A30<=Parametros!$B$10+3),1,0) | N30: =IF(M30=1,INDEX($D$18:$D$81,A30-3),0) | O30: =IF(M30=1,Parametros!$B$5*(1-Parametros!$B$12)*(1-Parametros!$B$11)^((A30+Parametros!$B$14)/12),0) | P30: =N30*(1+Parametros!$B$8)^(3+Parametros!$B$14) | Q30: =MIN(O30*(1-Parametros!$B$13),P30) | R30: =IF(M30=1,MAX(0,1-Q30/(1+Parametros!$B$20)^Parametros!$B$14/N30),0) | S30: =IF(M30=1,Parametros!$B$15*R30+(1-Parametros!$B$15),0) | T30: =IF(M30=1,-Parametros!$B$7-Parametros!$B$22+INDEX($G$18:$G$81,A30-3)+Parametros!$B$15*Q30/(1+Parametros!$B$20)^(A30+Parametros!$B$14),0) | U30: =IF(M30=1,INDEX($I$18:$I$81,A30-3),0) | V30: =IF(M30=1,-Parametros!$B$7-Parametros!$B$22+INDEX($L$18:$L$81,A30-3)+Parametros!$B$15*MIN(O30*(1-Parametros!$B$13),U30*(1+Parametros!$B$27)^(3+Parametros!$B$14))/(1+Parametros!$B$20)^(A30+Parametros!$B$14),0) | W30: =IF(M30=1,((A30-3)/(Parametros!$B$16-3))*EXP(1-(A30-3)/(Parametros!$B$16-3)),0) | X30: =W30+X29 | Y30: =W30/$B$9 | Z30: =S30*N30/(1+Parametros!$B$20)^A30 | AA30: =IF(AND(M30=1,O30*(1-Parametros!$B$13)>=N30),1,0)
... A81: 63 | B81: =IF(A81<=Parametros!$B$10,1,0) | C81: =IF(AND(A81>=1,A81<=Parametros!$B$10),$B$4,0) | D81: =IF(A81<=Parametros!$B$10,Parametros!$B$7*((1+Parametros!$B$8)^Parametros!$B$10-(1+Parametros!$B$8)^A81)/((1+Parametros!$B$8)^Parametros!$B$10-1),0) | E81: =IF(AND(A81>=1,A81<=Parametros!$B$10),Parametros!$B$21/12*D80,0) | F81: =C81-E81 | G81: =F81/(1+Parametros!$B$20)^A81+G80 | H81: =IF(AND(A81>=1,A81<=Parametros!$B$10),$B$5,0) | I81: =IF(A81<=Parametros!$B$10,Parametros!$B$7*((1+Parametros!$B$27)^Parametros!$B$10-(1+Parametros!$B$27)^A81)/((1+Parametros!$B$27)^Parametros!$B$10-1),0) | J81: =IF(AND(A81>=1,A81<=Parametros!$B$10),Parametros!$B$21/12*I80,0) | K81: =H81-J81 | L81: =K81/(1+Parametros!$B$20)^A81+L80 | M81: =IF(AND(A81>=4,A81<=Parametros!$B$10+3),1,0) | N81: =IF(M81=1,INDEX($D$18:$D$81,A81-3),0) | O81: =IF(M81=1,Parametros!$B$5*(1-Parametros!$B$12)*(1-Parametros!$B$11)^((A81+Parametros!$B$14)/12),0) | P81: =N81*(1+Parametros!$B$8)^(3+Parametros!$B$14) | Q81: =MIN(O81*(1-Parametros!$B$13),P81) | R81: =IF(M81=1,MAX(0,1-Q81/(1+Parametros!$B$20)^Parametros!$B$14/N81),0) | S81: =IF(M81=1,Parametros!$B$15*R81+(1-Parametros!$B$15),0) | T81: =IF(M81=1,-Parametros!$B$7-Parametros!$B$22+INDEX($G$18:$G$81,A81-3)+Parametros!$B$15*Q81/(1+Parametros!$B$20)^(A81+Parametros!$B$14),0) | U81: =IF(M81=1,INDEX($I$18:$I$81,A81-3),0) | V81: =IF(M81=1,-Parametros!$B$7-Parametros!$B$22+INDEX($L$18:$L$81,A81-3)+Parametros!$B$15*MIN(O81*(1-Parametros!$B$13),U81*(1+Parametros!$B$27)^(3+Parametros!$B$14))/(1+Parametros!$B$20)^(A81+Parametros!$B$14),0) | W81: =IF(M81=1,((A81-3)/(Parametros!$B$16-3))*EXP(1-(A81-3)/(Parametros!$B$16-3)),0) | X81: =W81+X80 | Y81: =W81/$B$9 | Z81: =S81*N81/(1+Parametros!$B$20)^A81 | AA81: =IF(AND(M81=1,O81*(1-Parametros!$B$13)>=N81),1,0)

Sheet Default_bandas
A1: Distribución de tiempos de default por banda (riesgos proporcionales)
A2: λ_b = −ln(1 − PD12_b)/S12; P(default en d) = exp(−λ_b·S(d−1)) − exp(−λ_b·S(d)). Las bandas riesgosas concentran sus malos antes (la supervivencia se agota).
C3: banda | D3: A1 | E3: A2 | F3: B1 | G3: B2 | H3: C1 | I3: C2 | J3: D | K3: E
C4: PD12 | D4: =Bandas!E5 | E4: =Bandas!E6 | F4: =Bandas!E7 | G4: =Bandas!E8 | H4: =Bandas!E9 | I4: =Bandas!E10 | J4: =Bandas!E11 | K4: =Bandas!E12
C5: λ_b (intensidad) | D5: =-LN(1-D4)/LGD_motos!$B$8 | E5: =-LN(1-E4)/LGD_motos!$B$8 | F5: =-LN(1-F4)/LGD_motos!$B$8 | G5: =-LN(1-G4)/LGD_motos!$B$8 | H5: =-LN(1-H4)/LGD_motos!$B$8 | I5: =-LN(1-I4)/LGD_motos!$B$8 | J5: =-LN(1-J4)/LGD_motos!$B$8 | K5: =-LN(1-K4)/LGD_motos!$B$8
C6: PD de vida (exacta) | D6: =1-EXP(-D5*LGD_motos!$B$9) | E6: =1-EXP(-E5*LGD_motos!$B$9) | F6: =1-EXP(-F5*LGD_motos!$B$9) | G6: =1-EXP(-G5*LGD_motos!$B$9) | H6: =1-EXP(-H5*LGD_motos!$B$9) | I6: =1-EXP(-I5*LGD_motos!$B$9) | J6: =1-EXP(-J5*LGD_motos!$B$9) | K6: =1-EXP(-K5*LGD_motos!$B$9)
C7: Σ f·VPN si malo (tasa base) | D7: =SUMPRODUCT(D18:D81,LGD_motos!$T$18:$T$81) | E7: =SUMPRODUCT(E18:E81,LGD_motos!$T$18:$T$81) | F7: =SUMPRODUCT(F18:F81,LGD_motos!$T$18:$T$81) | G7: =SUMPRODUCT(G18:G81,LGD_motos!$T$18:$T$81) | H7: =SUMPRODUCT(H18:H81,LGD_motos!$T$18:$T$81) | I7: =SUMPRODUCT(I18:I81,LGD_motos!$T$18:$T$81) | J7: =SUMPRODUCT(J18:J81,LGD_motos!$T$18:$T$81) | K7: =SUMPRODUCT(K18:K81,LGD_motos!$T$18:$T$81)
C8: Σ f·VPN si malo (TMC) | D8: =SUMPRODUCT(D18:D81,LGD_motos!$V$18:$V$81) | E8: =SUMPRODUCT(E18:E81,LGD_motos!$V$18:$V$81) | F8: =SUMPRODUCT(F18:F81,LGD_motos!$V$18:$V$81) | G8: =SUMPRODUCT(G18:G81,LGD_motos!$V$18:$V$81) | H8: =SUMPRODUCT(H18:H81,LGD_motos!$V$18:$V$81) | I8: =SUMPRODUCT(I18:I81,LGD_motos!$V$18:$V$81) | J8: =SUMPRODUCT(J18:J81,LGD_motos!$V$18:$V$81) | K8: =SUMPRODUCT(K18:K81,LGD_motos!$V$18:$V$81)
C9: EL por crédito (VP, monto M0) | D9: =SUMPRODUCT(D18:D81,LGD_motos!$Z$18:$Z$81) | E9: =SUMPRODUCT(E18:E81,LGD_motos!$Z$18:$Z$81) | F9: =SUMPRODUCT(F18:F81,LGD_motos!$Z$18:$Z$81) | G9: =SUMPRODUCT(G18:G81,LGD_motos!$Z$18:$Z$81) | H9: =SUMPRODUCT(H18:H81,LGD_motos!$Z$18:$Z$81) | I9: =SUMPRODUCT(I18:I81,LGD_motos!$Z$18:$Z$81) | J9: =SUMPRODUCT(J18:J81,LGD_motos!$Z$18:$Z$81) | K9: =SUMPRODUCT(K18:K81,LGD_motos!$Z$18:$Z$81)
A17: mes d | B17: S(d) | C17: S(d−1) | D17: P(default en d) · A1 | E17: P(default en d) · A2 | F17: P(default en d) · B1 | G17: P(default en d) · B2 | H17: P(default en d) · C1 | I17: P(default en d) · C2 | J17: P(default en d) · D | K17: P(default en d) · E
A18: =LGD_motos!A18 | B18: =LGD_motos!X18 | C18: =0 | D18: =EXP(-D$5*C18)-EXP(-D$5*B18) | E18: =EXP(-E$5*C18)-EXP(-E$5*B18) | F18: =EXP(-F$5*C18)-EXP(-F$5*B18) | G18: =EXP(-G$5*C18)-EXP(-G$5*B18) | H18: =EXP(-H$5*C18)-EXP(-H$5*B18) | I18: =EXP(-I$5*C18)-EXP(-I$5*B18) | J18: =EXP(-J$5*C18)-EXP(-J$5*B18) | K18: =EXP(-K$5*C18)-EXP(-K$5*B18)
A19: =LGD_motos!A19 | B19: =LGD_motos!X19 | C19: =B18 | D19: =EXP(-D$5*C19)-EXP(-D$5*B19) | E19: =EXP(-E$5*C19)-EXP(-E$5*B19) | F19: =EXP(-F$5*C19)-EXP(-F$5*B19) | G19: =EXP(-G$5*C19)-EXP(-G$5*B19) | H19: =EXP(-H$5*C19)-EXP(-H$5*B19) | I19: =EXP(-I$5*C19)-EXP(-I$5*B19) | J19: =EXP(-J$5*C19)-EXP(-J$5*B19) | K19: =EXP(-K$5*C19)-EXP(-K$5*B19)
A20: =LGD_motos!A20 | B20: =LGD_motos!X20 | C20: =B19 | D20: =EXP(-D$5*C20)-EXP(-D$5*B20) | E20: =EXP(-E$5*C20)-EXP(-E$5*B20) | F20: =EXP(-F$5*C20)-EXP(-F$5*B20) | G20: =EXP(-G$5*C20)-EXP(-G$5*B20) | H20: =EXP(-H$5*C20)-EXP(-H$5*B20) | I20: =EXP(-I$5*C20)-EXP(-I$5*B20) | J20: =EXP(-J$5*C20)-EXP(-J$5*B20) | K20: =EXP(-K$5*C20)-EXP(-K$5*B20)
A21: =LGD_motos!A21 | B21: =LGD_motos!X21 | C21: =B20 | D21: =EXP(-D$5*C21)-EXP(-D$5*B21) | E21: =EXP(-E$5*C21)-EXP(-E$5*B21) | F21: =EXP(-F$5*C21)-EXP(-F$5*B21) | G21: =EXP(-G$5*C21)-EXP(-G$5*B21) | H21: =EXP(-H$5*C21)-EXP(-H$5*B21) | I21: =EXP(-I$5*C21)-EXP(-I$5*B21) | J21: =EXP(-J$5*C21)-EXP(-J$5*B21) | K21: =EXP(-K$5*C21)-EXP(-K$5*B21)
A22: =LGD_motos!A22 | B22: =LGD_motos!X22 | C22: =B21 | D22: =EXP(-D$5*C22)-EXP(-D$5*B22) | E22: =EXP(-E$5*C22)-EXP(-E$5*B22) | F22: =EXP(-F$5*C22)-EXP(-F$5*B22) | G22: =EXP(-G$5*C22)-EXP(-G$5*B22) | H22: =EXP(-H$5*C22)-EXP(-H$5*B22) | I22: =EXP(-I$5*C22)-EXP(-I$5*B22) | J22: =EXP(-J$5*C22)-EXP(-J$5*B22) | K22: =EXP(-K$5*C22)-EXP(-K$5*B22)
A23: =LGD_motos!A23 | B23: =LGD_motos!X23 | C23: =B22 | D23: =EXP(-D$5*C23)-EXP(-D$5*B23) | E23: =EXP(-E$5*C23)-EXP(-E$5*B23) | F23: =EXP(-F$5*C23)-EXP(-F$5*B23) | G23: =EXP(-G$5*C23)-EXP(-G$5*B23) | H23: =EXP(-H$5*C23)-EXP(-H$5*B23) | I23: =EXP(-I$5*C23)-EXP(-I$5*B23) | J23: =EXP(-J$5*C23)-EXP(-J$5*B23) | K23: =EXP(-K$5*C23)-EXP(-K$5*B23)
A24: =LGD_motos!A24 | B24: =LGD_motos!X24 | C24: =B23 | D24: =EXP(-D$5*C24)-EXP(-D$5*B24) | E24: =EXP(-E$5*C24)-EXP(-E$5*B24) | F24: =EXP(-F$5*C24)-EXP(-F$5*B24) | G24: =EXP(-G$5*C24)-EXP(-G$5*B24) | H24: =EXP(-H$5*C24)-EXP(-H$5*B24) | I24: =EXP(-I$5*C24)-EXP(-I$5*B24) | J24: =EXP(-J$5*C24)-EXP(-J$5*B24) | K24: =EXP(-K$5*C24)-EXP(-K$5*B24)
A25: =LGD_motos!A25 | B25: =LGD_motos!X25 | C25: =B24 | D25: =EXP(-D$5*C25)-EXP(-D$5*B25) | E25: =EXP(-E$5*C25)-EXP(-E$5*B25) | F25: =EXP(-F$5*C25)-EXP(-F$5*B25) | G25: =EXP(-G$5*C25)-EXP(-G$5*B25) | H25: =EXP(-H$5*C25)-EXP(-H$5*B25) | I25: =EXP(-I$5*C25)-EXP(-I$5*B25) | J25: =EXP(-J$5*C25)-EXP(-J$5*B25) | K25: =EXP(-K$5*C25)-EXP(-K$5*B25)
A26: =LGD_motos!A26 | B26: =LGD_motos!X26 | C26: =B25 | D26: =EXP(-D$5*C26)-EXP(-D$5*B26) | E26: =EXP(-E$5*C26)-EXP(-E$5*B26) | F26: =EXP(-F$5*C26)-EXP(-F$5*B26) | G26: =EXP(-G$5*C26)-EXP(-G$5*B26) | H26: =EXP(-H$5*C26)-EXP(-H$5*B26) | I26: =EXP(-I$5*C26)-EXP(-I$5*B26) | J26: =EXP(-J$5*C26)-EXP(-J$5*B26) | K26: =EXP(-K$5*C26)-EXP(-K$5*B26)
A27: =LGD_motos!A27 | B27: =LGD_motos!X27 | C27: =B26 | D27: =EXP(-D$5*C27)-EXP(-D$5*B27) | E27: =EXP(-E$5*C27)-EXP(-E$5*B27) | F27: =EXP(-F$5*C27)-EXP(-F$5*B27) | G27: =EXP(-G$5*C27)-EXP(-G$5*B27) | H27: =EXP(-H$5*C27)-EXP(-H$5*B27) | I27: =EXP(-I$5*C27)-EXP(-I$5*B27) | J27: =EXP(-J$5*C27)-EXP(-J$5*B27) | K27: =EXP(-K$5*C27)-EXP(-K$5*B27)
A28: =LGD_motos!A28 | B28: =LGD_motos!X28 | C28: =B27 | D28: =EXP(-D$5*C28)-EXP(-D$5*B28) | E28: =EXP(-E$5*C28)-EXP(-E$5*B28) | F28: =EXP(-F$5*C28)-EXP(-F$5*B28) | G28: =EXP(-G$5*C28)-EXP(-G$5*B28) | H28: =EXP(-H$5*C28)-EXP(-H$5*B28) | I28: =EXP(-I$5*C28)-EXP(-I$5*B28) | J28: =EXP(-J$5*C28)-EXP(-J$5*B28) | K28: =EXP(-K$5*C28)-EXP(-K$5*B28)
A29: =LGD_motos!A29 | B29: =LGD_motos!X29 | C29: =B28 | D29: =EXP(-D$5*C29)-EXP(-D$5*B29) | E29: =EXP(-E$5*C29)-EXP(-E$5*B29) | F29: =EXP(-F$5*C29)-EXP(-F$5*B29) | G29: =EXP(-G$5*C29)-EXP(-G$5*B29) | H29: =EXP(-H$5*C29)-EXP(-H$5*B29) | I29: =EXP(-I$5*C29)-EXP(-I$5*B29) | J29: =EXP(-J$5*C29)-EXP(-J$5*B29) | K29: =EXP(-K$5*C29)-EXP(-K$5*B29)
A30: =LGD_motos!A30 | B30: =LGD_motos!X30 | C30: =B29 | D30: =EXP(-D$5*C30)-EXP(-D$5*B30) | E30: =EXP(-E$5*C30)-EXP(-E$5*B30) | F30: =EXP(-F$5*C30)-EXP(-F$5*B30) | G30: =EXP(-G$5*C30)-EXP(-G$5*B30) | H30: =EXP(-H$5*C30)-EXP(-H$5*B30) | I30: =EXP(-I$5*C30)-EXP(-I$5*B30) | J30: =EXP(-J$5*C30)-EXP(-J$5*B30) | K30: =EXP(-K$5*C30)-EXP(-K$5*B30)
... A81: =LGD_motos!A81 | B81: =LGD_motos!X81 | C81: =B80 | D81: =EXP(-D$5*C81)-EXP(-D$5*B81) | E81: =EXP(-E$5*C81)-EXP(-E$5*B81) | F81: =EXP(-F$5*C81)-EXP(-F$5*B81) | G81: =EXP(-G$5*C81)-EXP(-G$5*B81) | H81: =EXP(-H$5*C81)-EXP(-H$5*B81) | I81: =EXP(-I$5*C81)-EXP(-I$5*B81) | J81: =EXP(-J$5*C81)-EXP(-J$5*B81) | K81: =EXP(-K$5*C81)-EXP(-K$5*B81)
